2025-03-26 15:42:58,249 - EnterpriseDataCleaning - INFO - File saved: data/uploads\Example-3.xlsx
2025-03-26 15:43:03,127 - EnterpriseDataCleaning - INFO - Data loaded from file: data/uploads\Example-3.xlsx
2025-03-26 15:43:03,128 - EnterpriseDataCleaning - INFO - Data cleaning process completed.
2025-03-26 15:43:03,141 - EnterpriseDataCleaning - ERROR - Error saving cleaned data:
Traceback (most recent call last):
  File "C:\Users\Sai Varma\Desktop\Enterprise_Data_Cleaning\backend\services\data_cleaner_class.py", line 27, in save_cleaned_data
    writer.book = book
    ^^^^^^^^^^^
AttributeError: property 'book' of 'OpenpyxlWriter' object has no setter

During handling of the above exception, another exception occurred:

Traceback (most recent call last):
  File "C:\Users\Sai Varma\Desktop\Enterprise_Data_Cleaning\backend\services\data_cleaner_class.py", line 26, in save_cleaned_data
    with pd.ExcelWriter(self.file_path, engine='openpyxl') as writer:
  File "C:\Users\Sai Varma\AppData\Local\Programs\Python\Python311\Lib\site-packages\pandas\io\excel\_base.py", line 1370, in __exit__
    self.close()
  File "C:\Users\Sai Varma\AppData\Local\Programs\Python\Python311\Lib\site-packages\pandas\io\excel\_base.py", line 1374, in close
    self._save()
  File "C:\Users\Sai Varma\AppData\Local\Programs\Python\Python311\Lib\site-packages\pandas\io\excel\_openpyxl.py", line 110, in _save
    self.book.save(self._handles.handle)
  File "C:\Users\Sai Varma\AppData\Local\Programs\Python\Python311\Lib\site-packages\openpyxl\workbook\workbook.py", line 386, in save
    save_workbook(self, filename)
  File "C:\Users\Sai Varma\AppData\Local\Programs\Python\Python311\Lib\site-packages\openpyxl\writer\excel.py", line 294, in save_workbook
    writer.save()
  File "C:\Users\Sai Varma\AppData\Local\Programs\Python\Python311\Lib\site-packages\openpyxl\writer\excel.py", line 275, in save
    self.write_data()
  File "C:\Users\Sai Varma\AppData\Local\Programs\Python\Python311\Lib\site-packages\openpyxl\writer\excel.py", line 89, in write_data
    archive.writestr(ARC_WORKBOOK, writer.write())
                                   ^^^^^^^^^^^^^^
  File "C:\Users\Sai Varma\AppData\Local\Programs\Python\Python311\Lib\site-packages\openpyxl\workbook\_writer.py", line 150, in write
    self.write_views()
  File "C:\Users\Sai Varma\AppData\Local\Programs\Python\Python311\Lib\site-packages\openpyxl\workbook\_writer.py", line 137, in write_views
    active = get_active_sheet(self.wb)
             ^^^^^^^^^^^^^^^^^^^^^^^^^
  File "C:\Users\Sai Varma\AppData\Local\Programs\Python\Python311\Lib\site-packages\openpyxl\workbook\_writer.py", line 35, in get_active_sheet
    raise IndexError("At least one sheet must be visible")
IndexError: At least one sheet must be visible
2025-03-26 15:43:03,259 - EnterpriseDataCleaning - ERROR - Error during data cleaning:
Traceback (most recent call last):
  File "C:\Users\Sai Varma\Desktop\Enterprise_Data_Cleaning\backend\services\data_cleaner_class.py", line 27, in save_cleaned_data
    writer.book = book
    ^^^^^^^^^^^
AttributeError: property 'book' of 'OpenpyxlWriter' object has no setter

During handling of the above exception, another exception occurred:

Traceback (most recent call last):
  File "C:\Users\Sai Varma\Desktop\Enterprise_Data_Cleaning\backend\routes\file_routes.py", line 38, in clean_file
    result_path = data_cleaning.clean_data(file_path)
                  ^^^^^^^^^^^^^^^^^^^^^^^^^^^^^^^^^^^
  File "C:\Users\Sai Varma\Desktop\Enterprise_Data_Cleaning\backend\services\data_cleaning.py", line 7, in clean_data
    return cleaner.save_cleaned_data()
           ^^^^^^^^^^^^^^^^^^^^^^^^^^^
  File "C:\Users\Sai Varma\Desktop\Enterprise_Data_Cleaning\backend\services\data_cleaner_class.py", line 36, in save_cleaned_data
    raise e
  File "C:\Users\Sai Varma\Desktop\Enterprise_Data_Cleaning\backend\services\data_cleaner_class.py", line 26, in save_cleaned_data
    with pd.ExcelWriter(self.file_path, engine='openpyxl') as writer:
  File "C:\Users\Sai Varma\AppData\Local\Programs\Python\Python311\Lib\site-packages\pandas\io\excel\_base.py", line 1370, in __exit__
    self.close()
  File "C:\Users\Sai Varma\AppData\Local\Programs\Python\Python311\Lib\site-packages\pandas\io\excel\_base.py", line 1374, in close
    self._save()
  File "C:\Users\Sai Varma\AppData\Local\Programs\Python\Python311\Lib\site-packages\pandas\io\excel\_openpyxl.py", line 110, in _save
    self.book.save(self._handles.handle)
  File "C:\Users\Sai Varma\AppData\Local\Programs\Python\Python311\Lib\site-packages\openpyxl\workbook\workbook.py", line 386, in save
    save_workbook(self, filename)
  File "C:\Users\Sai Varma\AppData\Local\Programs\Python\Python311\Lib\site-packages\openpyxl\writer\excel.py", line 294, in save_workbook
    writer.save()
  File "C:\Users\Sai Varma\AppData\Local\Programs\Python\Python311\Lib\site-packages\openpyxl\writer\excel.py", line 275, in save
    self.write_data()
  File "C:\Users\Sai Varma\AppData\Local\Programs\Python\Python311\Lib\site-packages\openpyxl\writer\excel.py", line 89, in write_data
    archive.writestr(ARC_WORKBOOK, writer.write())
                                   ^^^^^^^^^^^^^^
  File "C:\Users\Sai Varma\AppData\Local\Programs\Python\Python311\Lib\site-packages\openpyxl\workbook\_writer.py", line 150, in write
    self.write_views()
  File "C:\Users\Sai Varma\AppData\Local\Programs\Python\Python311\Lib\site-packages\openpyxl\workbook\_writer.py", line 137, in write_views
    active = get_active_sheet(self.wb)
             ^^^^^^^^^^^^^^^^^^^^^^^^^
  File "C:\Users\Sai Varma\AppData\Local\Programs\Python\Python311\Lib\site-packages\openpyxl\workbook\_writer.py", line 35, in get_active_sheet
    raise IndexError("At least one sheet must be visible")
IndexError: At least one sheet must be visible
2025-03-26 16:02:59,391 - EnterpriseDataCleaning - INFO - File saved: data/uploads\Example-3.xlsx
2025-03-26 16:02:59,801 - EnterpriseDataCleaning - INFO - File analysis complete.
2025-03-26 16:03:06,894 - EnterpriseDataCleaning - INFO - Data loaded from file: data/uploads\Example-3.xlsx
2025-03-26 16:03:06,895 - EnterpriseDataCleaning - INFO - Data cleaning process completed.
2025-03-26 16:03:06,904 - EnterpriseDataCleaning - ERROR - Error saving cleaned data:
Traceback (most recent call last):
  File "C:\Users\Sai Varma\Desktop\Enterprise_Data_Cleaning\backend\services\data_cleaner_class.py", line 27, in save_cleaned_data
    writer.book = book
    ^^^^^^^^^^^
AttributeError: property 'book' of 'OpenpyxlWriter' object has no setter

During handling of the above exception, another exception occurred:

Traceback (most recent call last):
  File "C:\Users\Sai Varma\Desktop\Enterprise_Data_Cleaning\backend\services\data_cleaner_class.py", line 26, in save_cleaned_data
    with pd.ExcelWriter(self.file_path, engine='openpyxl') as writer:
  File "C:\Users\Sai Varma\AppData\Local\Programs\Python\Python311\Lib\site-packages\pandas\io\excel\_base.py", line 1370, in __exit__
    self.close()
  File "C:\Users\Sai Varma\AppData\Local\Programs\Python\Python311\Lib\site-packages\pandas\io\excel\_base.py", line 1374, in close
    self._save()
  File "C:\Users\Sai Varma\AppData\Local\Programs\Python\Python311\Lib\site-packages\pandas\io\excel\_openpyxl.py", line 110, in _save
    self.book.save(self._handles.handle)
  File "C:\Users\Sai Varma\AppData\Local\Programs\Python\Python311\Lib\site-packages\openpyxl\workbook\workbook.py", line 386, in save
    save_workbook(self, filename)
  File "C:\Users\Sai Varma\AppData\Local\Programs\Python\Python311\Lib\site-packages\openpyxl\writer\excel.py", line 294, in save_workbook
    writer.save()
  File "C:\Users\Sai Varma\AppData\Local\Programs\Python\Python311\Lib\site-packages\openpyxl\writer\excel.py", line 275, in save
    self.write_data()
  File "C:\Users\Sai Varma\AppData\Local\Programs\Python\Python311\Lib\site-packages\openpyxl\writer\excel.py", line 89, in write_data
    archive.writestr(ARC_WORKBOOK, writer.write())
                                   ^^^^^^^^^^^^^^
  File "C:\Users\Sai Varma\AppData\Local\Programs\Python\Python311\Lib\site-packages\openpyxl\workbook\_writer.py", line 150, in write
    self.write_views()
  File "C:\Users\Sai Varma\AppData\Local\Programs\Python\Python311\Lib\site-packages\openpyxl\workbook\_writer.py", line 137, in write_views
    active = get_active_sheet(self.wb)
             ^^^^^^^^^^^^^^^^^^^^^^^^^
  File "C:\Users\Sai Varma\AppData\Local\Programs\Python\Python311\Lib\site-packages\openpyxl\workbook\_writer.py", line 35, in get_active_sheet
    raise IndexError("At least one sheet must be visible")
IndexError: At least one sheet must be visible
2025-03-26 16:03:06,911 - EnterpriseDataCleaning - ERROR - Error during data cleaning:
Traceback (most recent call last):
  File "C:\Users\Sai Varma\Desktop\Enterprise_Data_Cleaning\backend\services\data_cleaner_class.py", line 27, in save_cleaned_data
    writer.book = book
    ^^^^^^^^^^^
AttributeError: property 'book' of 'OpenpyxlWriter' object has no setter

During handling of the above exception, another exception occurred:

Traceback (most recent call last):
  File "C:\Users\Sai Varma\Desktop\Enterprise_Data_Cleaning\backend\routes\file_routes.py", line 38, in clean_file
    result_path = data_cleaning.clean_data(file_path)
                  ^^^^^^^^^^^^^^^^^^^^^^^^^^^^^^^^^^^
  File "C:\Users\Sai Varma\Desktop\Enterprise_Data_Cleaning\backend\services\data_cleaning.py", line 7, in clean_data
    return cleaner.save_cleaned_data()
           ^^^^^^^^^^^^^^^^^^^^^^^^^^^
  File "C:\Users\Sai Varma\Desktop\Enterprise_Data_Cleaning\backend\services\data_cleaner_class.py", line 36, in save_cleaned_data
    raise e
  File "C:\Users\Sai Varma\Desktop\Enterprise_Data_Cleaning\backend\services\data_cleaner_class.py", line 26, in save_cleaned_data
    with pd.ExcelWriter(self.file_path, engine='openpyxl') as writer:
  File "C:\Users\Sai Varma\AppData\Local\Programs\Python\Python311\Lib\site-packages\pandas\io\excel\_base.py", line 1370, in __exit__
    self.close()
  File "C:\Users\Sai Varma\AppData\Local\Programs\Python\Python311\Lib\site-packages\pandas\io\excel\_base.py", line 1374, in close
    self._save()
  File "C:\Users\Sai Varma\AppData\Local\Programs\Python\Python311\Lib\site-packages\pandas\io\excel\_openpyxl.py", line 110, in _save
    self.book.save(self._handles.handle)
  File "C:\Users\Sai Varma\AppData\Local\Programs\Python\Python311\Lib\site-packages\openpyxl\workbook\workbook.py", line 386, in save
    save_workbook(self, filename)
  File "C:\Users\Sai Varma\AppData\Local\Programs\Python\Python311\Lib\site-packages\openpyxl\writer\excel.py", line 294, in save_workbook
    writer.save()
  File "C:\Users\Sai Varma\AppData\Local\Programs\Python\Python311\Lib\site-packages\openpyxl\writer\excel.py", line 275, in save
    self.write_data()
  File "C:\Users\Sai Varma\AppData\Local\Programs\Python\Python311\Lib\site-packages\openpyxl\writer\excel.py", line 89, in write_data
    archive.writestr(ARC_WORKBOOK, writer.write())
                                   ^^^^^^^^^^^^^^
  File "C:\Users\Sai Varma\AppData\Local\Programs\Python\Python311\Lib\site-packages\openpyxl\workbook\_writer.py", line 150, in write
    self.write_views()
  File "C:\Users\Sai Varma\AppData\Local\Programs\Python\Python311\Lib\site-packages\openpyxl\workbook\_writer.py", line 137, in write_views
    active = get_active_sheet(self.wb)
             ^^^^^^^^^^^^^^^^^^^^^^^^^
  File "C:\Users\Sai Varma\AppData\Local\Programs\Python\Python311\Lib\site-packages\openpyxl\workbook\_writer.py", line 35, in get_active_sheet
    raise IndexError("At least one sheet must be visible")
IndexError: At least one sheet must be visible
2025-03-26 16:03:21,321 - EnterpriseDataCleaning - INFO - File saved: data/uploads\Example-2.xlsx
2025-03-26 16:03:21,936 - EnterpriseDataCleaning - INFO - File analysis complete.
2025-03-26 16:03:32,656 - EnterpriseDataCleaning - INFO - Data loaded from file: data/uploads\Example-2.xlsx
2025-03-26 16:03:32,661 - EnterpriseDataCleaning - INFO - Data cleaning process completed.
2025-03-26 16:03:32,670 - EnterpriseDataCleaning - ERROR - Error saving cleaned data:
Traceback (most recent call last):
  File "C:\Users\Sai Varma\Desktop\Enterprise_Data_Cleaning\backend\services\data_cleaner_class.py", line 27, in save_cleaned_data
    writer.book = book
    ^^^^^^^^^^^
AttributeError: property 'book' of 'OpenpyxlWriter' object has no setter

During handling of the above exception, another exception occurred:

Traceback (most recent call last):
  File "C:\Users\Sai Varma\Desktop\Enterprise_Data_Cleaning\backend\services\data_cleaner_class.py", line 26, in save_cleaned_data
    with pd.ExcelWriter(self.file_path, engine='openpyxl') as writer:
  File "C:\Users\Sai Varma\AppData\Local\Programs\Python\Python311\Lib\site-packages\pandas\io\excel\_base.py", line 1370, in __exit__
    self.close()
  File "C:\Users\Sai Varma\AppData\Local\Programs\Python\Python311\Lib\site-packages\pandas\io\excel\_base.py", line 1374, in close
    self._save()
  File "C:\Users\Sai Varma\AppData\Local\Programs\Python\Python311\Lib\site-packages\pandas\io\excel\_openpyxl.py", line 110, in _save
    self.book.save(self._handles.handle)
  File "C:\Users\Sai Varma\AppData\Local\Programs\Python\Python311\Lib\site-packages\openpyxl\workbook\workbook.py", line 386, in save
    save_workbook(self, filename)
  File "C:\Users\Sai Varma\AppData\Local\Programs\Python\Python311\Lib\site-packages\openpyxl\writer\excel.py", line 294, in save_workbook
    writer.save()
  File "C:\Users\Sai Varma\AppData\Local\Programs\Python\Python311\Lib\site-packages\openpyxl\writer\excel.py", line 275, in save
    self.write_data()
  File "C:\Users\Sai Varma\AppData\Local\Programs\Python\Python311\Lib\site-packages\openpyxl\writer\excel.py", line 89, in write_data
    archive.writestr(ARC_WORKBOOK, writer.write())
                                   ^^^^^^^^^^^^^^
  File "C:\Users\Sai Varma\AppData\Local\Programs\Python\Python311\Lib\site-packages\openpyxl\workbook\_writer.py", line 150, in write
    self.write_views()
  File "C:\Users\Sai Varma\AppData\Local\Programs\Python\Python311\Lib\site-packages\openpyxl\workbook\_writer.py", line 137, in write_views
    active = get_active_sheet(self.wb)
             ^^^^^^^^^^^^^^^^^^^^^^^^^
  File "C:\Users\Sai Varma\AppData\Local\Programs\Python\Python311\Lib\site-packages\openpyxl\workbook\_writer.py", line 35, in get_active_sheet
    raise IndexError("At least one sheet must be visible")
IndexError: At least one sheet must be visible
2025-03-26 16:03:32,672 - EnterpriseDataCleaning - ERROR - Error during data cleaning:
Traceback (most recent call last):
  File "C:\Users\Sai Varma\Desktop\Enterprise_Data_Cleaning\backend\services\data_cleaner_class.py", line 27, in save_cleaned_data
    writer.book = book
    ^^^^^^^^^^^
AttributeError: property 'book' of 'OpenpyxlWriter' object has no setter

During handling of the above exception, another exception occurred:

Traceback (most recent call last):
  File "C:\Users\Sai Varma\Desktop\Enterprise_Data_Cleaning\backend\routes\file_routes.py", line 38, in clean_file
    result_path = data_cleaning.clean_data(file_path)
                  ^^^^^^^^^^^^^^^^^^^^^^^^^^^^^^^^^^^
  File "C:\Users\Sai Varma\Desktop\Enterprise_Data_Cleaning\backend\services\data_cleaning.py", line 7, in clean_data
    return cleaner.save_cleaned_data()
           ^^^^^^^^^^^^^^^^^^^^^^^^^^^
  File "C:\Users\Sai Varma\Desktop\Enterprise_Data_Cleaning\backend\services\data_cleaner_class.py", line 36, in save_cleaned_data
    raise e
  File "C:\Users\Sai Varma\Desktop\Enterprise_Data_Cleaning\backend\services\data_cleaner_class.py", line 26, in save_cleaned_data
    with pd.ExcelWriter(self.file_path, engine='openpyxl') as writer:
  File "C:\Users\Sai Varma\AppData\Local\Programs\Python\Python311\Lib\site-packages\pandas\io\excel\_base.py", line 1370, in __exit__
    self.close()
  File "C:\Users\Sai Varma\AppData\Local\Programs\Python\Python311\Lib\site-packages\pandas\io\excel\_base.py", line 1374, in close
    self._save()
  File "C:\Users\Sai Varma\AppData\Local\Programs\Python\Python311\Lib\site-packages\pandas\io\excel\_openpyxl.py", line 110, in _save
    self.book.save(self._handles.handle)
  File "C:\Users\Sai Varma\AppData\Local\Programs\Python\Python311\Lib\site-packages\openpyxl\workbook\workbook.py", line 386, in save
    save_workbook(self, filename)
  File "C:\Users\Sai Varma\AppData\Local\Programs\Python\Python311\Lib\site-packages\openpyxl\writer\excel.py", line 294, in save_workbook
    writer.save()
  File "C:\Users\Sai Varma\AppData\Local\Programs\Python\Python311\Lib\site-packages\openpyxl\writer\excel.py", line 275, in save
    self.write_data()
  File "C:\Users\Sai Varma\AppData\Local\Programs\Python\Python311\Lib\site-packages\openpyxl\writer\excel.py", line 89, in write_data
    archive.writestr(ARC_WORKBOOK, writer.write())
                                   ^^^^^^^^^^^^^^
  File "C:\Users\Sai Varma\AppData\Local\Programs\Python\Python311\Lib\site-packages\openpyxl\workbook\_writer.py", line 150, in write
    self.write_views()
  File "C:\Users\Sai Varma\AppData\Local\Programs\Python\Python311\Lib\site-packages\openpyxl\workbook\_writer.py", line 137, in write_views
    active = get_active_sheet(self.wb)
             ^^^^^^^^^^^^^^^^^^^^^^^^^
  File "C:\Users\Sai Varma\AppData\Local\Programs\Python\Python311\Lib\site-packages\openpyxl\workbook\_writer.py", line 35, in get_active_sheet
    raise IndexError("At least one sheet must be visible")
IndexError: At least one sheet must be visible
2025-03-26 16:09:01,475 - EnterpriseDataCleaning - INFO - File saved: data/uploads\version_1_1.xlsx
2025-03-26 16:09:01,820 - EnterpriseDataCleaning - INFO - File analysis complete.
2025-03-26 16:22:50,815 - EnterpriseDataCleaning - INFO - File saved: data/uploads\Example-3.xlsx
2025-03-26 16:22:51,221 - EnterpriseDataCleaning - INFO - File analysis complete.
2025-03-26 16:22:57,214 - EnterpriseDataCleaning - INFO - Data loaded from file: data/uploads\Example-3.xlsx
2025-03-26 16:22:57,218 - EnterpriseDataCleaning - INFO - Data cleaning process completed.
2025-03-26 16:22:57,238 - EnterpriseDataCleaning - ERROR - Error saving cleaned data:
Traceback (most recent call last):
  File "C:\Users\Sai Varma\Desktop\Enterprise_Data_Cleaning\backend\services\data_cleaner_class.py", line 27, in save_cleaned_data
    writer.book = book
    ^^^^^^^^^^^
AttributeError: property 'book' of 'OpenpyxlWriter' object has no setter

During handling of the above exception, another exception occurred:

Traceback (most recent call last):
  File "C:\Users\Sai Varma\Desktop\Enterprise_Data_Cleaning\backend\services\data_cleaner_class.py", line 26, in save_cleaned_data
    with pd.ExcelWriter(self.file_path, engine='openpyxl') as writer:
  File "C:\Users\Sai Varma\AppData\Local\Programs\Python\Python311\Lib\site-packages\pandas\io\excel\_base.py", line 1370, in __exit__
    self.close()
  File "C:\Users\Sai Varma\AppData\Local\Programs\Python\Python311\Lib\site-packages\pandas\io\excel\_base.py", line 1374, in close
    self._save()
  File "C:\Users\Sai Varma\AppData\Local\Programs\Python\Python311\Lib\site-packages\pandas\io\excel\_openpyxl.py", line 110, in _save
    self.book.save(self._handles.handle)
  File "C:\Users\Sai Varma\AppData\Local\Programs\Python\Python311\Lib\site-packages\openpyxl\workbook\workbook.py", line 386, in save
    save_workbook(self, filename)
  File "C:\Users\Sai Varma\AppData\Local\Programs\Python\Python311\Lib\site-packages\openpyxl\writer\excel.py", line 294, in save_workbook
    writer.save()
  File "C:\Users\Sai Varma\AppData\Local\Programs\Python\Python311\Lib\site-packages\openpyxl\writer\excel.py", line 275, in save
    self.write_data()
  File "C:\Users\Sai Varma\AppData\Local\Programs\Python\Python311\Lib\site-packages\openpyxl\writer\excel.py", line 89, in write_data
    archive.writestr(ARC_WORKBOOK, writer.write())
                                   ^^^^^^^^^^^^^^
  File "C:\Users\Sai Varma\AppData\Local\Programs\Python\Python311\Lib\site-packages\openpyxl\workbook\_writer.py", line 150, in write
    self.write_views()
  File "C:\Users\Sai Varma\AppData\Local\Programs\Python\Python311\Lib\site-packages\openpyxl\workbook\_writer.py", line 137, in write_views
    active = get_active_sheet(self.wb)
             ^^^^^^^^^^^^^^^^^^^^^^^^^
  File "C:\Users\Sai Varma\AppData\Local\Programs\Python\Python311\Lib\site-packages\openpyxl\workbook\_writer.py", line 35, in get_active_sheet
    raise IndexError("At least one sheet must be visible")
IndexError: At least one sheet must be visible
2025-03-26 16:22:57,252 - EnterpriseDataCleaning - ERROR - Error during data cleaning:
Traceback (most recent call last):
  File "C:\Users\Sai Varma\Desktop\Enterprise_Data_Cleaning\backend\services\data_cleaner_class.py", line 27, in save_cleaned_data
    writer.book = book
    ^^^^^^^^^^^
AttributeError: property 'book' of 'OpenpyxlWriter' object has no setter

During handling of the above exception, another exception occurred:

Traceback (most recent call last):
  File "C:\Users\Sai Varma\Desktop\Enterprise_Data_Cleaning\backend\routes\file_routes.py", line 38, in clean_file
    result_path = data_cleaning.clean_data(file_path)
                  ^^^^^^^^^^^^^^^^^^^^^^^^^^^^^^^^^^^
  File "C:\Users\Sai Varma\Desktop\Enterprise_Data_Cleaning\backend\services\data_cleaning.py", line 7, in clean_data
    return cleaner.save_cleaned_data()
           ^^^^^^^^^^^^^^^^^^^^^^^^^^^
  File "C:\Users\Sai Varma\Desktop\Enterprise_Data_Cleaning\backend\services\data_cleaner_class.py", line 36, in save_cleaned_data
    raise e
  File "C:\Users\Sai Varma\Desktop\Enterprise_Data_Cleaning\backend\services\data_cleaner_class.py", line 26, in save_cleaned_data
    with pd.ExcelWriter(self.file_path, engine='openpyxl') as writer:
  File "C:\Users\Sai Varma\AppData\Local\Programs\Python\Python311\Lib\site-packages\pandas\io\excel\_base.py", line 1370, in __exit__
    self.close()
  File "C:\Users\Sai Varma\AppData\Local\Programs\Python\Python311\Lib\site-packages\pandas\io\excel\_base.py", line 1374, in close
    self._save()
  File "C:\Users\Sai Varma\AppData\Local\Programs\Python\Python311\Lib\site-packages\pandas\io\excel\_openpyxl.py", line 110, in _save
    self.book.save(self._handles.handle)
  File "C:\Users\Sai Varma\AppData\Local\Programs\Python\Python311\Lib\site-packages\openpyxl\workbook\workbook.py", line 386, in save
    save_workbook(self, filename)
  File "C:\Users\Sai Varma\AppData\Local\Programs\Python\Python311\Lib\site-packages\openpyxl\writer\excel.py", line 294, in save_workbook
    writer.save()
  File "C:\Users\Sai Varma\AppData\Local\Programs\Python\Python311\Lib\site-packages\openpyxl\writer\excel.py", line 275, in save
    self.write_data()
  File "C:\Users\Sai Varma\AppData\Local\Programs\Python\Python311\Lib\site-packages\openpyxl\writer\excel.py", line 89, in write_data
    archive.writestr(ARC_WORKBOOK, writer.write())
                                   ^^^^^^^^^^^^^^
  File "C:\Users\Sai Varma\AppData\Local\Programs\Python\Python311\Lib\site-packages\openpyxl\workbook\_writer.py", line 150, in write
    self.write_views()
  File "C:\Users\Sai Varma\AppData\Local\Programs\Python\Python311\Lib\site-packages\openpyxl\workbook\_writer.py", line 137, in write_views
    active = get_active_sheet(self.wb)
             ^^^^^^^^^^^^^^^^^^^^^^^^^
  File "C:\Users\Sai Varma\AppData\Local\Programs\Python\Python311\Lib\site-packages\openpyxl\workbook\_writer.py", line 35, in get_active_sheet
    raise IndexError("At least one sheet must be visible")
IndexError: At least one sheet must be visible
2025-03-26 16:49:49,279 - EnterpriseDataCleaning - INFO - File saved: data/uploads\sample1_1.xlsx
2025-03-26 16:49:49,638 - EnterpriseDataCleaning - INFO - File analysis complete.
2025-03-26 16:52:55,518 - EnterpriseDataCleaning - INFO - File saved: data/uploads\sample2.xlsx
2025-03-26 16:52:55,866 - EnterpriseDataCleaning - INFO - File analysis complete.
2025-03-26 16:53:18,983 - EnterpriseDataCleaning - INFO - Data loaded from file: data/uploads\sample2.xlsx
2025-03-26 16:53:18,997 - EnterpriseDataCleaning - INFO - Data cleaning process completed.
2025-03-26 16:53:19,007 - EnterpriseDataCleaning - ERROR - Error saving cleaned data:
Traceback (most recent call last):
  File "C:\Users\Sai Varma\Desktop\Enterprise_Data_Cleaning\backend\services\data_cleaner_class.py", line 27, in save_cleaned_data
    writer.book = book
    ^^^^^^^^^^^
AttributeError: property 'book' of 'OpenpyxlWriter' object has no setter

During handling of the above exception, another exception occurred:

Traceback (most recent call last):
  File "C:\Users\Sai Varma\Desktop\Enterprise_Data_Cleaning\backend\services\data_cleaner_class.py", line 26, in save_cleaned_data
    with pd.ExcelWriter(self.file_path, engine='openpyxl') as writer:
  File "C:\Users\Sai Varma\AppData\Local\Programs\Python\Python311\Lib\site-packages\pandas\io\excel\_base.py", line 1370, in __exit__
    self.close()
  File "C:\Users\Sai Varma\AppData\Local\Programs\Python\Python311\Lib\site-packages\pandas\io\excel\_base.py", line 1374, in close
    self._save()
  File "C:\Users\Sai Varma\AppData\Local\Programs\Python\Python311\Lib\site-packages\pandas\io\excel\_openpyxl.py", line 110, in _save
    self.book.save(self._handles.handle)
  File "C:\Users\Sai Varma\AppData\Local\Programs\Python\Python311\Lib\site-packages\openpyxl\workbook\workbook.py", line 386, in save
    save_workbook(self, filename)
  File "C:\Users\Sai Varma\AppData\Local\Programs\Python\Python311\Lib\site-packages\openpyxl\writer\excel.py", line 294, in save_workbook
    writer.save()
  File "C:\Users\Sai Varma\AppData\Local\Programs\Python\Python311\Lib\site-packages\openpyxl\writer\excel.py", line 275, in save
    self.write_data()
  File "C:\Users\Sai Varma\AppData\Local\Programs\Python\Python311\Lib\site-packages\openpyxl\writer\excel.py", line 89, in write_data
    archive.writestr(ARC_WORKBOOK, writer.write())
                                   ^^^^^^^^^^^^^^
  File "C:\Users\Sai Varma\AppData\Local\Programs\Python\Python311\Lib\site-packages\openpyxl\workbook\_writer.py", line 150, in write
    self.write_views()
  File "C:\Users\Sai Varma\AppData\Local\Programs\Python\Python311\Lib\site-packages\openpyxl\workbook\_writer.py", line 137, in write_views
    active = get_active_sheet(self.wb)
             ^^^^^^^^^^^^^^^^^^^^^^^^^
  File "C:\Users\Sai Varma\AppData\Local\Programs\Python\Python311\Lib\site-packages\openpyxl\workbook\_writer.py", line 35, in get_active_sheet
    raise IndexError("At least one sheet must be visible")
IndexError: At least one sheet must be visible
2025-03-26 16:53:19,010 - EnterpriseDataCleaning - ERROR - Error during data cleaning:
Traceback (most recent call last):
  File "C:\Users\Sai Varma\Desktop\Enterprise_Data_Cleaning\backend\services\data_cleaner_class.py", line 27, in save_cleaned_data
    writer.book = book
    ^^^^^^^^^^^
AttributeError: property 'book' of 'OpenpyxlWriter' object has no setter

During handling of the above exception, another exception occurred:

Traceback (most recent call last):
  File "C:\Users\Sai Varma\Desktop\Enterprise_Data_Cleaning\backend\routes\file_routes.py", line 38, in clean_file
    result_path = data_cleaning.clean_data(file_path)
                  ^^^^^^^^^^^^^^^^^^^^^^^^^^^^^^^^^^^
  File "C:\Users\Sai Varma\Desktop\Enterprise_Data_Cleaning\backend\services\data_cleaning.py", line 7, in clean_data
    return cleaner.save_cleaned_data()
           ^^^^^^^^^^^^^^^^^^^^^^^^^^^
  File "C:\Users\Sai Varma\Desktop\Enterprise_Data_Cleaning\backend\services\data_cleaner_class.py", line 36, in save_cleaned_data
    raise e
  File "C:\Users\Sai Varma\Desktop\Enterprise_Data_Cleaning\backend\services\data_cleaner_class.py", line 26, in save_cleaned_data
    with pd.ExcelWriter(self.file_path, engine='openpyxl') as writer:
  File "C:\Users\Sai Varma\AppData\Local\Programs\Python\Python311\Lib\site-packages\pandas\io\excel\_base.py", line 1370, in __exit__
    self.close()
  File "C:\Users\Sai Varma\AppData\Local\Programs\Python\Python311\Lib\site-packages\pandas\io\excel\_base.py", line 1374, in close
    self._save()
  File "C:\Users\Sai Varma\AppData\Local\Programs\Python\Python311\Lib\site-packages\pandas\io\excel\_openpyxl.py", line 110, in _save
    self.book.save(self._handles.handle)
  File "C:\Users\Sai Varma\AppData\Local\Programs\Python\Python311\Lib\site-packages\openpyxl\workbook\workbook.py", line 386, in save
    save_workbook(self, filename)
  File "C:\Users\Sai Varma\AppData\Local\Programs\Python\Python311\Lib\site-packages\openpyxl\writer\excel.py", line 294, in save_workbook
    writer.save()
  File "C:\Users\Sai Varma\AppData\Local\Programs\Python\Python311\Lib\site-packages\openpyxl\writer\excel.py", line 275, in save
    self.write_data()
  File "C:\Users\Sai Varma\AppData\Local\Programs\Python\Python311\Lib\site-packages\openpyxl\writer\excel.py", line 89, in write_data
    archive.writestr(ARC_WORKBOOK, writer.write())
                                   ^^^^^^^^^^^^^^
  File "C:\Users\Sai Varma\AppData\Local\Programs\Python\Python311\Lib\site-packages\openpyxl\workbook\_writer.py", line 150, in write
    self.write_views()
  File "C:\Users\Sai Varma\AppData\Local\Programs\Python\Python311\Lib\site-packages\openpyxl\workbook\_writer.py", line 137, in write_views
    active = get_active_sheet(self.wb)
             ^^^^^^^^^^^^^^^^^^^^^^^^^
  File "C:\Users\Sai Varma\AppData\Local\Programs\Python\Python311\Lib\site-packages\openpyxl\workbook\_writer.py", line 35, in get_active_sheet
    raise IndexError("At least one sheet must be visible")
IndexError: At least one sheet must be visible
2025-03-26 17:03:32,664 - EnterpriseDataCleaning - ERROR - Error during file analysis:
Traceback (most recent call last):
  File "C:\Users\Sai Varma\Desktop\Enterprise_Data_Cleaning\backend\services\analysis_service.py", line 8, in analyze_file
    df = pd.read_excel(file_path, sheet_name='Actual Data')
         ^^^^^^^^^^^^^^^^^^^^^^^^^^^^^^^^^^^^^^^^^^^^^^^^^^
  File "C:\Users\Sai Varma\AppData\Local\Programs\Python\Python311\Lib\site-packages\pandas\io\excel\_base.py", line 504, in read_excel
    io = ExcelFile(
         ^^^^^^^^^^
  File "C:\Users\Sai Varma\AppData\Local\Programs\Python\Python311\Lib\site-packages\pandas\io\excel\_base.py", line 1572, in __init__
    engine = config.get_option(f"io.excel.{ext}.reader", silent=True)
             ^^^^^^^^^^^^^^^^^^^^^^^^^^^^^^^^^^^^^^^^^^^^^^^^^^^^^^^^
  File "C:\Users\Sai Varma\AppData\Local\Programs\Python\Python311\Lib\site-packages\pandas\_config\config.py", line 272, in __call__
    return self.__func__(*args, **kwds)
           ^^^^^^^^^^^^^^^^^^^^^^^^^^^^
  File "C:\Users\Sai Varma\AppData\Local\Programs\Python\Python311\Lib\site-packages\pandas\_config\config.py", line 146, in _get_option
    key = _get_single_key(pat, silent)
          ^^^^^^^^^^^^^^^^^^^^^^^^^^^^
  File "C:\Users\Sai Varma\AppData\Local\Programs\Python\Python311\Lib\site-packages\pandas\_config\config.py", line 132, in _get_single_key
    raise OptionError(f"No such keys(s): {repr(pat)}")
pandas._config.config.OptionError: No such keys(s): 'io.excel.zip.reader'

During handling of the above exception, another exception occurred:

Traceback (most recent call last):
  File "C:\Users\Sai Varma\Desktop\Enterprise_Data_Cleaning\backend\services\analysis_service.py", line 10, in analyze_file
    df = pd.read_excel(file_path, sheet_name=0)
         ^^^^^^^^^^^^^^^^^^^^^^^^^^^^^^^^^^^^^^
  File "C:\Users\Sai Varma\AppData\Local\Programs\Python\Python311\Lib\site-packages\pandas\io\excel\_base.py", line 504, in read_excel
    io = ExcelFile(
         ^^^^^^^^^^
  File "C:\Users\Sai Varma\AppData\Local\Programs\Python\Python311\Lib\site-packages\pandas\io\excel\_base.py", line 1572, in __init__
    engine = config.get_option(f"io.excel.{ext}.reader", silent=True)
             ^^^^^^^^^^^^^^^^^^^^^^^^^^^^^^^^^^^^^^^^^^^^^^^^^^^^^^^^
  File "C:\Users\Sai Varma\AppData\Local\Programs\Python\Python311\Lib\site-packages\pandas\_config\config.py", line 272, in __call__
    return self.__func__(*args, **kwds)
           ^^^^^^^^^^^^^^^^^^^^^^^^^^^^
  File "C:\Users\Sai Varma\AppData\Local\Programs\Python\Python311\Lib\site-packages\pandas\_config\config.py", line 146, in _get_option
    key = _get_single_key(pat, silent)
          ^^^^^^^^^^^^^^^^^^^^^^^^^^^^
  File "C:\Users\Sai Varma\AppData\Local\Programs\Python\Python311\Lib\site-packages\pandas\_config\config.py", line 132, in _get_single_key
    raise OptionError(f"No such keys(s): {repr(pat)}")
pandas._config.config.OptionError: No such keys(s): 'io.excel.zip.reader'
2025-03-26 17:03:32,688 - EnterpriseDataCleaning - ERROR - Error during file analysis:
Traceback (most recent call last):
  File "C:\Users\Sai Varma\Desktop\Enterprise_Data_Cleaning\backend\services\analysis_service.py", line 8, in analyze_file
    df = pd.read_excel(file_path, sheet_name='Actual Data')
         ^^^^^^^^^^^^^^^^^^^^^^^^^^^^^^^^^^^^^^^^^^^^^^^^^^
  File "C:\Users\Sai Varma\AppData\Local\Programs\Python\Python311\Lib\site-packages\pandas\io\excel\_base.py", line 504, in read_excel
    io = ExcelFile(
         ^^^^^^^^^^
  File "C:\Users\Sai Varma\AppData\Local\Programs\Python\Python311\Lib\site-packages\pandas\io\excel\_base.py", line 1572, in __init__
    engine = config.get_option(f"io.excel.{ext}.reader", silent=True)
             ^^^^^^^^^^^^^^^^^^^^^^^^^^^^^^^^^^^^^^^^^^^^^^^^^^^^^^^^
  File "C:\Users\Sai Varma\AppData\Local\Programs\Python\Python311\Lib\site-packages\pandas\_config\config.py", line 272, in __call__
    return self.__func__(*args, **kwds)
           ^^^^^^^^^^^^^^^^^^^^^^^^^^^^
  File "C:\Users\Sai Varma\AppData\Local\Programs\Python\Python311\Lib\site-packages\pandas\_config\config.py", line 146, in _get_option
    key = _get_single_key(pat, silent)
          ^^^^^^^^^^^^^^^^^^^^^^^^^^^^
  File "C:\Users\Sai Varma\AppData\Local\Programs\Python\Python311\Lib\site-packages\pandas\_config\config.py", line 132, in _get_single_key
    raise OptionError(f"No such keys(s): {repr(pat)}")
pandas._config.config.OptionError: No such keys(s): 'io.excel.zip.reader'

During handling of the above exception, another exception occurred:

Traceback (most recent call last):
  File "C:\Users\Sai Varma\Desktop\Enterprise_Data_Cleaning\backend\routes\file_routes.py", line 57, in analyze_file
    analysis = analysis_service.analyze_file(file_path)
               ^^^^^^^^^^^^^^^^^^^^^^^^^^^^^^^^^^^^^^^^
  File "C:\Users\Sai Varma\Desktop\Enterprise_Data_Cleaning\backend\services\analysis_service.py", line 26, in analyze_file
    raise e
  File "C:\Users\Sai Varma\Desktop\Enterprise_Data_Cleaning\backend\services\analysis_service.py", line 10, in analyze_file
    df = pd.read_excel(file_path, sheet_name=0)
         ^^^^^^^^^^^^^^^^^^^^^^^^^^^^^^^^^^^^^^
  File "C:\Users\Sai Varma\AppData\Local\Programs\Python\Python311\Lib\site-packages\pandas\io\excel\_base.py", line 504, in read_excel
    io = ExcelFile(
         ^^^^^^^^^^
  File "C:\Users\Sai Varma\AppData\Local\Programs\Python\Python311\Lib\site-packages\pandas\io\excel\_base.py", line 1572, in __init__
    engine = config.get_option(f"io.excel.{ext}.reader", silent=True)
             ^^^^^^^^^^^^^^^^^^^^^^^^^^^^^^^^^^^^^^^^^^^^^^^^^^^^^^^^
  File "C:\Users\Sai Varma\AppData\Local\Programs\Python\Python311\Lib\site-packages\pandas\_config\config.py", line 272, in __call__
    return self.__func__(*args, **kwds)
           ^^^^^^^^^^^^^^^^^^^^^^^^^^^^
  File "C:\Users\Sai Varma\AppData\Local\Programs\Python\Python311\Lib\site-packages\pandas\_config\config.py", line 146, in _get_option
    key = _get_single_key(pat, silent)
          ^^^^^^^^^^^^^^^^^^^^^^^^^^^^
  File "C:\Users\Sai Varma\AppData\Local\Programs\Python\Python311\Lib\site-packages\pandas\_config\config.py", line 132, in _get_single_key
    raise OptionError(f"No such keys(s): {repr(pat)}")
pandas._config.config.OptionError: No such keys(s): 'io.excel.zip.reader'
2025-03-26 17:03:42,391 - EnterpriseDataCleaning - ERROR - Error during file analysis:
Traceback (most recent call last):
  File "C:\Users\Sai Varma\Desktop\Enterprise_Data_Cleaning\backend\services\analysis_service.py", line 8, in analyze_file
    df = pd.read_excel(file_path, sheet_name='Actual Data')
         ^^^^^^^^^^^^^^^^^^^^^^^^^^^^^^^^^^^^^^^^^^^^^^^^^^
  File "C:\Users\Sai Varma\AppData\Local\Programs\Python\Python311\Lib\site-packages\pandas\io\excel\_base.py", line 504, in read_excel
    io = ExcelFile(
         ^^^^^^^^^^
  File "C:\Users\Sai Varma\AppData\Local\Programs\Python\Python311\Lib\site-packages\pandas\io\excel\_base.py", line 1572, in __init__
    engine = config.get_option(f"io.excel.{ext}.reader", silent=True)
             ^^^^^^^^^^^^^^^^^^^^^^^^^^^^^^^^^^^^^^^^^^^^^^^^^^^^^^^^
  File "C:\Users\Sai Varma\AppData\Local\Programs\Python\Python311\Lib\site-packages\pandas\_config\config.py", line 272, in __call__
    return self.__func__(*args, **kwds)
           ^^^^^^^^^^^^^^^^^^^^^^^^^^^^
  File "C:\Users\Sai Varma\AppData\Local\Programs\Python\Python311\Lib\site-packages\pandas\_config\config.py", line 146, in _get_option
    key = _get_single_key(pat, silent)
          ^^^^^^^^^^^^^^^^^^^^^^^^^^^^
  File "C:\Users\Sai Varma\AppData\Local\Programs\Python\Python311\Lib\site-packages\pandas\_config\config.py", line 132, in _get_single_key
    raise OptionError(f"No such keys(s): {repr(pat)}")
pandas._config.config.OptionError: No such keys(s): 'io.excel.zip.reader'

During handling of the above exception, another exception occurred:

Traceback (most recent call last):
  File "C:\Users\Sai Varma\Desktop\Enterprise_Data_Cleaning\backend\services\analysis_service.py", line 10, in analyze_file
    df = pd.read_excel(file_path, sheet_name=0)
         ^^^^^^^^^^^^^^^^^^^^^^^^^^^^^^^^^^^^^^
  File "C:\Users\Sai Varma\AppData\Local\Programs\Python\Python311\Lib\site-packages\pandas\io\excel\_base.py", line 504, in read_excel
    io = ExcelFile(
         ^^^^^^^^^^
  File "C:\Users\Sai Varma\AppData\Local\Programs\Python\Python311\Lib\site-packages\pandas\io\excel\_base.py", line 1572, in __init__
    engine = config.get_option(f"io.excel.{ext}.reader", silent=True)
             ^^^^^^^^^^^^^^^^^^^^^^^^^^^^^^^^^^^^^^^^^^^^^^^^^^^^^^^^
  File "C:\Users\Sai Varma\AppData\Local\Programs\Python\Python311\Lib\site-packages\pandas\_config\config.py", line 272, in __call__
    return self.__func__(*args, **kwds)
           ^^^^^^^^^^^^^^^^^^^^^^^^^^^^
  File "C:\Users\Sai Varma\AppData\Local\Programs\Python\Python311\Lib\site-packages\pandas\_config\config.py", line 146, in _get_option
    key = _get_single_key(pat, silent)
          ^^^^^^^^^^^^^^^^^^^^^^^^^^^^
  File "C:\Users\Sai Varma\AppData\Local\Programs\Python\Python311\Lib\site-packages\pandas\_config\config.py", line 132, in _get_single_key
    raise OptionError(f"No such keys(s): {repr(pat)}")
pandas._config.config.OptionError: No such keys(s): 'io.excel.zip.reader'
2025-03-26 17:03:42,392 - EnterpriseDataCleaning - ERROR - Error during file analysis:
Traceback (most recent call last):
  File "C:\Users\Sai Varma\Desktop\Enterprise_Data_Cleaning\backend\services\analysis_service.py", line 8, in analyze_file
    df = pd.read_excel(file_path, sheet_name='Actual Data')
         ^^^^^^^^^^^^^^^^^^^^^^^^^^^^^^^^^^^^^^^^^^^^^^^^^^
  File "C:\Users\Sai Varma\AppData\Local\Programs\Python\Python311\Lib\site-packages\pandas\io\excel\_base.py", line 504, in read_excel
    io = ExcelFile(
         ^^^^^^^^^^
  File "C:\Users\Sai Varma\AppData\Local\Programs\Python\Python311\Lib\site-packages\pandas\io\excel\_base.py", line 1572, in __init__
    engine = config.get_option(f"io.excel.{ext}.reader", silent=True)
             ^^^^^^^^^^^^^^^^^^^^^^^^^^^^^^^^^^^^^^^^^^^^^^^^^^^^^^^^
  File "C:\Users\Sai Varma\AppData\Local\Programs\Python\Python311\Lib\site-packages\pandas\_config\config.py", line 272, in __call__
    return self.__func__(*args, **kwds)
           ^^^^^^^^^^^^^^^^^^^^^^^^^^^^
  File "C:\Users\Sai Varma\AppData\Local\Programs\Python\Python311\Lib\site-packages\pandas\_config\config.py", line 146, in _get_option
    key = _get_single_key(pat, silent)
          ^^^^^^^^^^^^^^^^^^^^^^^^^^^^
  File "C:\Users\Sai Varma\AppData\Local\Programs\Python\Python311\Lib\site-packages\pandas\_config\config.py", line 132, in _get_single_key
    raise OptionError(f"No such keys(s): {repr(pat)}")
pandas._config.config.OptionError: No such keys(s): 'io.excel.zip.reader'

During handling of the above exception, another exception occurred:

Traceback (most recent call last):
  File "C:\Users\Sai Varma\Desktop\Enterprise_Data_Cleaning\backend\routes\file_routes.py", line 57, in analyze_file
    analysis = analysis_service.analyze_file(file_path)
               ^^^^^^^^^^^^^^^^^^^^^^^^^^^^^^^^^^^^^^^^
  File "C:\Users\Sai Varma\Desktop\Enterprise_Data_Cleaning\backend\services\analysis_service.py", line 26, in analyze_file
    raise e
  File "C:\Users\Sai Varma\Desktop\Enterprise_Data_Cleaning\backend\services\analysis_service.py", line 10, in analyze_file
    df = pd.read_excel(file_path, sheet_name=0)
         ^^^^^^^^^^^^^^^^^^^^^^^^^^^^^^^^^^^^^^
  File "C:\Users\Sai Varma\AppData\Local\Programs\Python\Python311\Lib\site-packages\pandas\io\excel\_base.py", line 504, in read_excel
    io = ExcelFile(
         ^^^^^^^^^^
  File "C:\Users\Sai Varma\AppData\Local\Programs\Python\Python311\Lib\site-packages\pandas\io\excel\_base.py", line 1572, in __init__
    engine = config.get_option(f"io.excel.{ext}.reader", silent=True)
             ^^^^^^^^^^^^^^^^^^^^^^^^^^^^^^^^^^^^^^^^^^^^^^^^^^^^^^^^
  File "C:\Users\Sai Varma\AppData\Local\Programs\Python\Python311\Lib\site-packages\pandas\_config\config.py", line 272, in __call__
    return self.__func__(*args, **kwds)
           ^^^^^^^^^^^^^^^^^^^^^^^^^^^^
  File "C:\Users\Sai Varma\AppData\Local\Programs\Python\Python311\Lib\site-packages\pandas\_config\config.py", line 146, in _get_option
    key = _get_single_key(pat, silent)
          ^^^^^^^^^^^^^^^^^^^^^^^^^^^^
  File "C:\Users\Sai Varma\AppData\Local\Programs\Python\Python311\Lib\site-packages\pandas\_config\config.py", line 132, in _get_single_key
    raise OptionError(f"No such keys(s): {repr(pat)}")
pandas._config.config.OptionError: No such keys(s): 'io.excel.zip.reader'
2025-03-26 17:03:49,480 - EnterpriseDataCleaning - INFO - File saved: data/uploads\Example-3.xlsx
2025-03-26 17:03:50,092 - EnterpriseDataCleaning - INFO - File analysis complete.
2025-03-26 17:04:00,257 - EnterpriseDataCleaning - ERROR - Error during data cleaning:
Traceback (most recent call last):
  File "C:\Users\Sai Varma\Desktop\Enterprise_Data_Cleaning\backend\services\data_cleaning.py", line 23, in clean_data
    writer.book = book
    ^^^^^^^^^^^
AttributeError: property 'book' of 'OpenpyxlWriter' object has no setter

During handling of the above exception, another exception occurred:

Traceback (most recent call last):
  File "C:\Users\Sai Varma\Desktop\Enterprise_Data_Cleaning\backend\routes\file_routes.py", line 38, in clean_file
    result_path = data_cleaning.clean_data(file_path)
                  ^^^^^^^^^^^^^^^^^^^^^^^^^^^^^^^^^^^
  File "C:\Users\Sai Varma\Desktop\Enterprise_Data_Cleaning\backend\services\data_cleaning.py", line 22, in clean_data
    with pd.ExcelWriter(file_path, engine='openpyxl') as writer:
  File "C:\Users\Sai Varma\AppData\Local\Programs\Python\Python311\Lib\site-packages\pandas\io\excel\_base.py", line 1370, in __exit__
    self.close()
  File "C:\Users\Sai Varma\AppData\Local\Programs\Python\Python311\Lib\site-packages\pandas\io\excel\_base.py", line 1374, in close
    self._save()
  File "C:\Users\Sai Varma\AppData\Local\Programs\Python\Python311\Lib\site-packages\pandas\io\excel\_openpyxl.py", line 110, in _save
    self.book.save(self._handles.handle)
  File "C:\Users\Sai Varma\AppData\Local\Programs\Python\Python311\Lib\site-packages\openpyxl\workbook\workbook.py", line 386, in save
    save_workbook(self, filename)
  File "C:\Users\Sai Varma\AppData\Local\Programs\Python\Python311\Lib\site-packages\openpyxl\writer\excel.py", line 294, in save_workbook
    writer.save()
  File "C:\Users\Sai Varma\AppData\Local\Programs\Python\Python311\Lib\site-packages\openpyxl\writer\excel.py", line 275, in save
    self.write_data()
  File "C:\Users\Sai Varma\AppData\Local\Programs\Python\Python311\Lib\site-packages\openpyxl\writer\excel.py", line 89, in write_data
    archive.writestr(ARC_WORKBOOK, writer.write())
                                   ^^^^^^^^^^^^^^
  File "C:\Users\Sai Varma\AppData\Local\Programs\Python\Python311\Lib\site-packages\openpyxl\workbook\_writer.py", line 150, in write
    self.write_views()
  File "C:\Users\Sai Varma\AppData\Local\Programs\Python\Python311\Lib\site-packages\openpyxl\workbook\_writer.py", line 137, in write_views
    active = get_active_sheet(self.wb)
             ^^^^^^^^^^^^^^^^^^^^^^^^^
  File "C:\Users\Sai Varma\AppData\Local\Programs\Python\Python311\Lib\site-packages\openpyxl\workbook\_writer.py", line 35, in get_active_sheet
    raise IndexError("At least one sheet must be visible")
IndexError: At least one sheet must be visible
2025-03-26 17:05:06,522 - EnterpriseDataCleaning - INFO - File saved: data/uploads\Example-2.xlsx
2025-03-26 17:05:06,867 - EnterpriseDataCleaning - INFO - File analysis complete.
2025-03-26 17:13:20,231 - EnterpriseDataCleaning - ERROR - Error during file analysis:
Traceback (most recent call last):
  File "C:\Users\Sai Varma\Desktop\Enterprise_Data_Cleaning\backend\services\analysis_service.py", line 9, in analyze_file
    df = pd.read_excel(file_path, sheet_name='Actual Data', mangle_dupe_cols=False)
         ^^^^^^^^^^^^^^^^^^^^^^^^^^^^^^^^^^^^^^^^^^^^^^^^^^^^^^^^^^^^^^^^^^^^^^^^^^
TypeError: read_excel() got an unexpected keyword argument 'mangle_dupe_cols'

During handling of the above exception, another exception occurred:

Traceback (most recent call last):
  File "C:\Users\Sai Varma\Desktop\Enterprise_Data_Cleaning\backend\services\analysis_service.py", line 11, in analyze_file
    df = pd.read_excel(file_path, sheet_name=0, mangle_dupe_cols=False)
         ^^^^^^^^^^^^^^^^^^^^^^^^^^^^^^^^^^^^^^^^^^^^^^^^^^^^^^^^^^^^^^
TypeError: read_excel() got an unexpected keyword argument 'mangle_dupe_cols'
2025-03-26 17:13:20,235 - EnterpriseDataCleaning - ERROR - Error during file analysis:
Traceback (most recent call last):
  File "C:\Users\Sai Varma\Desktop\Enterprise_Data_Cleaning\backend\services\analysis_service.py", line 9, in analyze_file
    df = pd.read_excel(file_path, sheet_name='Actual Data', mangle_dupe_cols=False)
         ^^^^^^^^^^^^^^^^^^^^^^^^^^^^^^^^^^^^^^^^^^^^^^^^^^^^^^^^^^^^^^^^^^^^^^^^^^
TypeError: read_excel() got an unexpected keyword argument 'mangle_dupe_cols'

During handling of the above exception, another exception occurred:

Traceback (most recent call last):
  File "C:\Users\Sai Varma\Desktop\Enterprise_Data_Cleaning\backend\routes\file_routes.py", line 57, in analyze_file
    analysis = analysis_service.analyze_file(file_path)
               ^^^^^^^^^^^^^^^^^^^^^^^^^^^^^^^^^^^^^^^^
  File "C:\Users\Sai Varma\Desktop\Enterprise_Data_Cleaning\backend\services\analysis_service.py", line 40, in analyze_file
    raise e
  File "C:\Users\Sai Varma\Desktop\Enterprise_Data_Cleaning\backend\services\analysis_service.py", line 11, in analyze_file
    df = pd.read_excel(file_path, sheet_name=0, mangle_dupe_cols=False)
         ^^^^^^^^^^^^^^^^^^^^^^^^^^^^^^^^^^^^^^^^^^^^^^^^^^^^^^^^^^^^^^
TypeError: read_excel() got an unexpected keyword argument 'mangle_dupe_cols'
2025-03-26 17:13:29,357 - EnterpriseDataCleaning - INFO - File saved: data/uploads\Example-2.xlsx
2025-03-26 17:13:29,951 - EnterpriseDataCleaning - ERROR - Error during file analysis:
Traceback (most recent call last):
  File "C:\Users\Sai Varma\Desktop\Enterprise_Data_Cleaning\backend\services\analysis_service.py", line 9, in analyze_file
    df = pd.read_excel(file_path, sheet_name='Actual Data', mangle_dupe_cols=False)
         ^^^^^^^^^^^^^^^^^^^^^^^^^^^^^^^^^^^^^^^^^^^^^^^^^^^^^^^^^^^^^^^^^^^^^^^^^^
TypeError: read_excel() got an unexpected keyword argument 'mangle_dupe_cols'

During handling of the above exception, another exception occurred:

Traceback (most recent call last):
  File "C:\Users\Sai Varma\Desktop\Enterprise_Data_Cleaning\backend\services\analysis_service.py", line 11, in analyze_file
    df = pd.read_excel(file_path, sheet_name=0, mangle_dupe_cols=False)
         ^^^^^^^^^^^^^^^^^^^^^^^^^^^^^^^^^^^^^^^^^^^^^^^^^^^^^^^^^^^^^^
TypeError: read_excel() got an unexpected keyword argument 'mangle_dupe_cols'
2025-03-26 17:13:29,952 - EnterpriseDataCleaning - ERROR - Error during file analysis:
Traceback (most recent call last):
  File "C:\Users\Sai Varma\Desktop\Enterprise_Data_Cleaning\backend\services\analysis_service.py", line 9, in analyze_file
    df = pd.read_excel(file_path, sheet_name='Actual Data', mangle_dupe_cols=False)
         ^^^^^^^^^^^^^^^^^^^^^^^^^^^^^^^^^^^^^^^^^^^^^^^^^^^^^^^^^^^^^^^^^^^^^^^^^^
TypeError: read_excel() got an unexpected keyword argument 'mangle_dupe_cols'

During handling of the above exception, another exception occurred:

Traceback (most recent call last):
  File "C:\Users\Sai Varma\Desktop\Enterprise_Data_Cleaning\backend\routes\file_routes.py", line 57, in analyze_file
    analysis = analysis_service.analyze_file(file_path)
               ^^^^^^^^^^^^^^^^^^^^^^^^^^^^^^^^^^^^^^^^
  File "C:\Users\Sai Varma\Desktop\Enterprise_Data_Cleaning\backend\services\analysis_service.py", line 40, in analyze_file
    raise e
  File "C:\Users\Sai Varma\Desktop\Enterprise_Data_Cleaning\backend\services\analysis_service.py", line 11, in analyze_file
    df = pd.read_excel(file_path, sheet_name=0, mangle_dupe_cols=False)
         ^^^^^^^^^^^^^^^^^^^^^^^^^^^^^^^^^^^^^^^^^^^^^^^^^^^^^^^^^^^^^^
TypeError: read_excel() got an unexpected keyword argument 'mangle_dupe_cols'
2025-03-26 17:13:47,076 - EnterpriseDataCleaning - INFO - File saved: data/uploads\Example-3.xlsx
2025-03-26 17:13:47,662 - EnterpriseDataCleaning - ERROR - Error during file analysis:
Traceback (most recent call last):
  File "C:\Users\Sai Varma\Desktop\Enterprise_Data_Cleaning\backend\services\analysis_service.py", line 9, in analyze_file
    df = pd.read_excel(file_path, sheet_name='Actual Data', mangle_dupe_cols=False)
         ^^^^^^^^^^^^^^^^^^^^^^^^^^^^^^^^^^^^^^^^^^^^^^^^^^^^^^^^^^^^^^^^^^^^^^^^^^
TypeError: read_excel() got an unexpected keyword argument 'mangle_dupe_cols'

During handling of the above exception, another exception occurred:

Traceback (most recent call last):
  File "C:\Users\Sai Varma\Desktop\Enterprise_Data_Cleaning\backend\services\analysis_service.py", line 11, in analyze_file
    df = pd.read_excel(file_path, sheet_name=0, mangle_dupe_cols=False)
         ^^^^^^^^^^^^^^^^^^^^^^^^^^^^^^^^^^^^^^^^^^^^^^^^^^^^^^^^^^^^^^
TypeError: read_excel() got an unexpected keyword argument 'mangle_dupe_cols'
2025-03-26 17:13:47,663 - EnterpriseDataCleaning - ERROR - Error during file analysis:
Traceback (most recent call last):
  File "C:\Users\Sai Varma\Desktop\Enterprise_Data_Cleaning\backend\services\analysis_service.py", line 9, in analyze_file
    df = pd.read_excel(file_path, sheet_name='Actual Data', mangle_dupe_cols=False)
         ^^^^^^^^^^^^^^^^^^^^^^^^^^^^^^^^^^^^^^^^^^^^^^^^^^^^^^^^^^^^^^^^^^^^^^^^^^
TypeError: read_excel() got an unexpected keyword argument 'mangle_dupe_cols'

During handling of the above exception, another exception occurred:

Traceback (most recent call last):
  File "C:\Users\Sai Varma\Desktop\Enterprise_Data_Cleaning\backend\routes\file_routes.py", line 57, in analyze_file
    analysis = analysis_service.analyze_file(file_path)
               ^^^^^^^^^^^^^^^^^^^^^^^^^^^^^^^^^^^^^^^^
  File "C:\Users\Sai Varma\Desktop\Enterprise_Data_Cleaning\backend\services\analysis_service.py", line 40, in analyze_file
    raise e
  File "C:\Users\Sai Varma\Desktop\Enterprise_Data_Cleaning\backend\services\analysis_service.py", line 11, in analyze_file
    df = pd.read_excel(file_path, sheet_name=0, mangle_dupe_cols=False)
         ^^^^^^^^^^^^^^^^^^^^^^^^^^^^^^^^^^^^^^^^^^^^^^^^^^^^^^^^^^^^^^
TypeError: read_excel() got an unexpected keyword argument 'mangle_dupe_cols'
2025-03-26 17:16:29,296 - EnterpriseDataCleaning - ERROR - Error during file analysis:
Traceback (most recent call last):
  File "C:\Users\Sai Varma\Desktop\Enterprise_Data_Cleaning\backend\services\analysis_service.py", line 35, in analyze_file
    removed_message = f"Duplicate columns removed: {', '.join(duplicate_columns)}"
                                                    ^^^^^^^^^^^^^^^^^^^^^^^^^^^^
TypeError: sequence item 0: expected str instance, NoneType found
2025-03-26 17:16:29,297 - EnterpriseDataCleaning - ERROR - Error during file analysis:
Traceback (most recent call last):
  File "C:\Users\Sai Varma\Desktop\Enterprise_Data_Cleaning\backend\routes\file_routes.py", line 57, in analyze_file
    analysis = analysis_service.analyze_file(file_path)
               ^^^^^^^^^^^^^^^^^^^^^^^^^^^^^^^^^^^^^^^^
  File "C:\Users\Sai Varma\Desktop\Enterprise_Data_Cleaning\backend\services\analysis_service.py", line 50, in analyze_file
    raise e
  File "C:\Users\Sai Varma\Desktop\Enterprise_Data_Cleaning\backend\services\analysis_service.py", line 35, in analyze_file
    removed_message = f"Duplicate columns removed: {', '.join(duplicate_columns)}"
                                                    ^^^^^^^^^^^^^^^^^^^^^^^^^^^^
TypeError: sequence item 0: expected str instance, NoneType found
2025-03-26 17:16:30,844 - EnterpriseDataCleaning - ERROR - Error during file analysis:
Traceback (most recent call last):
  File "C:\Users\Sai Varma\Desktop\Enterprise_Data_Cleaning\backend\services\analysis_service.py", line 35, in analyze_file
    removed_message = f"Duplicate columns removed: {', '.join(duplicate_columns)}"
                                                    ^^^^^^^^^^^^^^^^^^^^^^^^^^^^
TypeError: sequence item 0: expected str instance, NoneType found
2025-03-26 17:16:30,845 - EnterpriseDataCleaning - ERROR - Error during file analysis:
Traceback (most recent call last):
  File "C:\Users\Sai Varma\Desktop\Enterprise_Data_Cleaning\backend\routes\file_routes.py", line 57, in analyze_file
    analysis = analysis_service.analyze_file(file_path)
               ^^^^^^^^^^^^^^^^^^^^^^^^^^^^^^^^^^^^^^^^
  File "C:\Users\Sai Varma\Desktop\Enterprise_Data_Cleaning\backend\services\analysis_service.py", line 50, in analyze_file
    raise e
  File "C:\Users\Sai Varma\Desktop\Enterprise_Data_Cleaning\backend\services\analysis_service.py", line 35, in analyze_file
    removed_message = f"Duplicate columns removed: {', '.join(duplicate_columns)}"
                                                    ^^^^^^^^^^^^^^^^^^^^^^^^^^^^
TypeError: sequence item 0: expected str instance, NoneType found
2025-03-26 17:16:38,923 - EnterpriseDataCleaning - INFO - File saved: data/uploads\Example-3.xlsx
2025-03-26 17:16:39,320 - EnterpriseDataCleaning - ERROR - Error during file analysis:
Traceback (most recent call last):
  File "C:\Users\Sai Varma\Desktop\Enterprise_Data_Cleaning\backend\services\analysis_service.py", line 35, in analyze_file
    removed_message = f"Duplicate columns removed: {', '.join(duplicate_columns)}"
                                                    ^^^^^^^^^^^^^^^^^^^^^^^^^^^^
TypeError: sequence item 0: expected str instance, NoneType found
2025-03-26 17:16:39,321 - EnterpriseDataCleaning - ERROR - Error during file analysis:
Traceback (most recent call last):
  File "C:\Users\Sai Varma\Desktop\Enterprise_Data_Cleaning\backend\routes\file_routes.py", line 57, in analyze_file
    analysis = analysis_service.analyze_file(file_path)
               ^^^^^^^^^^^^^^^^^^^^^^^^^^^^^^^^^^^^^^^^
  File "C:\Users\Sai Varma\Desktop\Enterprise_Data_Cleaning\backend\services\analysis_service.py", line 50, in analyze_file
    raise e
  File "C:\Users\Sai Varma\Desktop\Enterprise_Data_Cleaning\backend\services\analysis_service.py", line 35, in analyze_file
    removed_message = f"Duplicate columns removed: {', '.join(duplicate_columns)}"
                                                    ^^^^^^^^^^^^^^^^^^^^^^^^^^^^
TypeError: sequence item 0: expected str instance, NoneType found
2025-03-26 17:18:55,875 - EnterpriseDataCleaning - INFO - File analysis complete.
2025-03-26 17:19:09,743 - EnterpriseDataCleaning - INFO - File saved: data/uploads\Example-2.xlsx
2025-03-26 17:19:10,402 - EnterpriseDataCleaning - INFO - File analysis complete.
2025-03-26 17:24:37,275 - EnterpriseDataCleaning - INFO - File analysis complete.
2025-03-26 17:32:39,381 - EnterpriseDataCleaning - INFO - File analysis complete.
2025-03-26 17:36:21,549 - EnterpriseDataCleaning - ERROR - Error during file analysis:
Traceback (most recent call last):
  File "C:\Users\Sai Varma\Desktop\Enterprise_Data_Cleaning\backend\services\analysis_service.py", line 36, in analyze_file
    empty_columns = [col for col in df.columns if df[col].isnull().all()]
                    ^^^^^^^^^^^^^^^^^^^^^^^^^^^^^^^^^^^^^^^^^^^^^^^^^^^^^
  File "C:\Users\Sai Varma\Desktop\Enterprise_Data_Cleaning\backend\services\analysis_service.py", line 36, in <listcomp>
    empty_columns = [col for col in df.columns if df[col].isnull().all()]
                    ^^^^^^^^^^^^^^^^^^^^^^^^^^^^^^^^^^^^^^^^^^^^^^^^^^^^^
  File "C:\Users\Sai Varma\AppData\Local\Programs\Python\Python311\Lib\site-packages\pandas\core\generic.py", line 1519, in __nonzero__
    raise ValueError(
ValueError: The truth value of a Series is ambiguous. Use a.empty, a.bool(), a.item(), a.any() or a.all().
2025-03-26 17:36:21,633 - EnterpriseDataCleaning - ERROR - Error during file analysis:
Traceback (most recent call last):
  File "C:\Users\Sai Varma\Desktop\Enterprise_Data_Cleaning\backend\routes\file_routes.py", line 57, in analyze_file
    analysis = analysis_service.analyze_file(file_path)
               ^^^^^^^^^^^^^^^^^^^^^^^^^^^^^^^^^^^^^^^^
  File "C:\Users\Sai Varma\Desktop\Enterprise_Data_Cleaning\backend\services\analysis_service.py", line 79, in analyze_file
    raise e
  File "C:\Users\Sai Varma\Desktop\Enterprise_Data_Cleaning\backend\services\analysis_service.py", line 36, in analyze_file
    empty_columns = [col for col in df.columns if df[col].isnull().all()]
                    ^^^^^^^^^^^^^^^^^^^^^^^^^^^^^^^^^^^^^^^^^^^^^^^^^^^^^
  File "C:\Users\Sai Varma\Desktop\Enterprise_Data_Cleaning\backend\services\analysis_service.py", line 36, in <listcomp>
    empty_columns = [col for col in df.columns if df[col].isnull().all()]
                    ^^^^^^^^^^^^^^^^^^^^^^^^^^^^^^^^^^^^^^^^^^^^^^^^^^^^^
  File "C:\Users\Sai Varma\AppData\Local\Programs\Python\Python311\Lib\site-packages\pandas\core\generic.py", line 1519, in __nonzero__
    raise ValueError(
ValueError: The truth value of a Series is ambiguous. Use a.empty, a.bool(), a.item(), a.any() or a.all().
2025-03-26 17:37:48,732 - EnterpriseDataCleaning - ERROR - Error during file analysis:
Traceback (most recent call last):
  File "C:\Users\Sai Varma\Desktop\Enterprise_Data_Cleaning\backend\services\analysis_service.py", line 36, in analyze_file
    empty_columns = [col for col in df.columns if df[col].isnull().all()]
                    ^^^^^^^^^^^^^^^^^^^^^^^^^^^^^^^^^^^^^^^^^^^^^^^^^^^^^
  File "C:\Users\Sai Varma\Desktop\Enterprise_Data_Cleaning\backend\services\analysis_service.py", line 36, in <listcomp>
    empty_columns = [col for col in df.columns if df[col].isnull().all()]
                    ^^^^^^^^^^^^^^^^^^^^^^^^^^^^^^^^^^^^^^^^^^^^^^^^^^^^^
  File "C:\Users\Sai Varma\AppData\Local\Programs\Python\Python311\Lib\site-packages\pandas\core\generic.py", line 1519, in __nonzero__
    raise ValueError(
ValueError: The truth value of a Series is ambiguous. Use a.empty, a.bool(), a.item(), a.any() or a.all().
2025-03-26 17:37:48,737 - EnterpriseDataCleaning - ERROR - Error during file analysis:
Traceback (most recent call last):
  File "C:\Users\Sai Varma\Desktop\Enterprise_Data_Cleaning\backend\routes\file_routes.py", line 57, in analyze_file
    analysis = analysis_service.analyze_file(file_path)
               ^^^^^^^^^^^^^^^^^^^^^^^^^^^^^^^^^^^^^^^^
  File "C:\Users\Sai Varma\Desktop\Enterprise_Data_Cleaning\backend\services\analysis_service.py", line 79, in analyze_file
    raise e
  File "C:\Users\Sai Varma\Desktop\Enterprise_Data_Cleaning\backend\services\analysis_service.py", line 36, in analyze_file
    empty_columns = [col for col in df.columns if df[col].isnull().all()]
                    ^^^^^^^^^^^^^^^^^^^^^^^^^^^^^^^^^^^^^^^^^^^^^^^^^^^^^
  File "C:\Users\Sai Varma\Desktop\Enterprise_Data_Cleaning\backend\services\analysis_service.py", line 36, in <listcomp>
    empty_columns = [col for col in df.columns if df[col].isnull().all()]
                    ^^^^^^^^^^^^^^^^^^^^^^^^^^^^^^^^^^^^^^^^^^^^^^^^^^^^^
  File "C:\Users\Sai Varma\AppData\Local\Programs\Python\Python311\Lib\site-packages\pandas\core\generic.py", line 1519, in __nonzero__
    raise ValueError(
ValueError: The truth value of a Series is ambiguous. Use a.empty, a.bool(), a.item(), a.any() or a.all().
2025-03-26 17:37:49,620 - EnterpriseDataCleaning - ERROR - Error during file analysis:
Traceback (most recent call last):
  File "C:\Users\Sai Varma\Desktop\Enterprise_Data_Cleaning\backend\services\analysis_service.py", line 36, in analyze_file
    empty_columns = [col for col in df.columns if df[col].isnull().all()]
                    ^^^^^^^^^^^^^^^^^^^^^^^^^^^^^^^^^^^^^^^^^^^^^^^^^^^^^
  File "C:\Users\Sai Varma\Desktop\Enterprise_Data_Cleaning\backend\services\analysis_service.py", line 36, in <listcomp>
    empty_columns = [col for col in df.columns if df[col].isnull().all()]
                    ^^^^^^^^^^^^^^^^^^^^^^^^^^^^^^^^^^^^^^^^^^^^^^^^^^^^^
  File "C:\Users\Sai Varma\AppData\Local\Programs\Python\Python311\Lib\site-packages\pandas\core\generic.py", line 1519, in __nonzero__
    raise ValueError(
ValueError: The truth value of a Series is ambiguous. Use a.empty, a.bool(), a.item(), a.any() or a.all().
2025-03-26 17:37:49,622 - EnterpriseDataCleaning - ERROR - Error during file analysis:
Traceback (most recent call last):
  File "C:\Users\Sai Varma\Desktop\Enterprise_Data_Cleaning\backend\routes\file_routes.py", line 57, in analyze_file
    analysis = analysis_service.analyze_file(file_path)
               ^^^^^^^^^^^^^^^^^^^^^^^^^^^^^^^^^^^^^^^^
  File "C:\Users\Sai Varma\Desktop\Enterprise_Data_Cleaning\backend\services\analysis_service.py", line 79, in analyze_file
    raise e
  File "C:\Users\Sai Varma\Desktop\Enterprise_Data_Cleaning\backend\services\analysis_service.py", line 36, in analyze_file
    empty_columns = [col for col in df.columns if df[col].isnull().all()]
                    ^^^^^^^^^^^^^^^^^^^^^^^^^^^^^^^^^^^^^^^^^^^^^^^^^^^^^
  File "C:\Users\Sai Varma\Desktop\Enterprise_Data_Cleaning\backend\services\analysis_service.py", line 36, in <listcomp>
    empty_columns = [col for col in df.columns if df[col].isnull().all()]
                    ^^^^^^^^^^^^^^^^^^^^^^^^^^^^^^^^^^^^^^^^^^^^^^^^^^^^^
  File "C:\Users\Sai Varma\AppData\Local\Programs\Python\Python311\Lib\site-packages\pandas\core\generic.py", line 1519, in __nonzero__
    raise ValueError(
ValueError: The truth value of a Series is ambiguous. Use a.empty, a.bool(), a.item(), a.any() or a.all().
2025-03-26 17:37:50,851 - EnterpriseDataCleaning - ERROR - Error during file analysis:
Traceback (most recent call last):
  File "C:\Users\Sai Varma\Desktop\Enterprise_Data_Cleaning\backend\services\analysis_service.py", line 36, in analyze_file
    empty_columns = [col for col in df.columns if df[col].isnull().all()]
                    ^^^^^^^^^^^^^^^^^^^^^^^^^^^^^^^^^^^^^^^^^^^^^^^^^^^^^
  File "C:\Users\Sai Varma\Desktop\Enterprise_Data_Cleaning\backend\services\analysis_service.py", line 36, in <listcomp>
    empty_columns = [col for col in df.columns if df[col].isnull().all()]
                    ^^^^^^^^^^^^^^^^^^^^^^^^^^^^^^^^^^^^^^^^^^^^^^^^^^^^^
  File "C:\Users\Sai Varma\AppData\Local\Programs\Python\Python311\Lib\site-packages\pandas\core\generic.py", line 1519, in __nonzero__
    raise ValueError(
ValueError: The truth value of a Series is ambiguous. Use a.empty, a.bool(), a.item(), a.any() or a.all().
2025-03-26 17:37:50,852 - EnterpriseDataCleaning - ERROR - Error during file analysis:
Traceback (most recent call last):
  File "C:\Users\Sai Varma\Desktop\Enterprise_Data_Cleaning\backend\routes\file_routes.py", line 57, in analyze_file
    analysis = analysis_service.analyze_file(file_path)
               ^^^^^^^^^^^^^^^^^^^^^^^^^^^^^^^^^^^^^^^^
  File "C:\Users\Sai Varma\Desktop\Enterprise_Data_Cleaning\backend\services\analysis_service.py", line 79, in analyze_file
    raise e
  File "C:\Users\Sai Varma\Desktop\Enterprise_Data_Cleaning\backend\services\analysis_service.py", line 36, in analyze_file
    empty_columns = [col for col in df.columns if df[col].isnull().all()]
                    ^^^^^^^^^^^^^^^^^^^^^^^^^^^^^^^^^^^^^^^^^^^^^^^^^^^^^
  File "C:\Users\Sai Varma\Desktop\Enterprise_Data_Cleaning\backend\services\analysis_service.py", line 36, in <listcomp>
    empty_columns = [col for col in df.columns if df[col].isnull().all()]
                    ^^^^^^^^^^^^^^^^^^^^^^^^^^^^^^^^^^^^^^^^^^^^^^^^^^^^^
  File "C:\Users\Sai Varma\AppData\Local\Programs\Python\Python311\Lib\site-packages\pandas\core\generic.py", line 1519, in __nonzero__
    raise ValueError(
ValueError: The truth value of a Series is ambiguous. Use a.empty, a.bool(), a.item(), a.any() or a.all().
2025-03-26 17:37:51,171 - EnterpriseDataCleaning - ERROR - Error during file analysis:
Traceback (most recent call last):
  File "C:\Users\Sai Varma\Desktop\Enterprise_Data_Cleaning\backend\services\analysis_service.py", line 36, in analyze_file
    empty_columns = [col for col in df.columns if df[col].isnull().all()]
                    ^^^^^^^^^^^^^^^^^^^^^^^^^^^^^^^^^^^^^^^^^^^^^^^^^^^^^
  File "C:\Users\Sai Varma\Desktop\Enterprise_Data_Cleaning\backend\services\analysis_service.py", line 36, in <listcomp>
    empty_columns = [col for col in df.columns if df[col].isnull().all()]
                    ^^^^^^^^^^^^^^^^^^^^^^^^^^^^^^^^^^^^^^^^^^^^^^^^^^^^^
  File "C:\Users\Sai Varma\AppData\Local\Programs\Python\Python311\Lib\site-packages\pandas\core\generic.py", line 1519, in __nonzero__
    raise ValueError(
ValueError: The truth value of a Series is ambiguous. Use a.empty, a.bool(), a.item(), a.any() or a.all().
2025-03-26 17:37:51,174 - EnterpriseDataCleaning - ERROR - Error during file analysis:
Traceback (most recent call last):
  File "C:\Users\Sai Varma\Desktop\Enterprise_Data_Cleaning\backend\routes\file_routes.py", line 57, in analyze_file
    analysis = analysis_service.analyze_file(file_path)
               ^^^^^^^^^^^^^^^^^^^^^^^^^^^^^^^^^^^^^^^^
  File "C:\Users\Sai Varma\Desktop\Enterprise_Data_Cleaning\backend\services\analysis_service.py", line 79, in analyze_file
    raise e
  File "C:\Users\Sai Varma\Desktop\Enterprise_Data_Cleaning\backend\services\analysis_service.py", line 36, in analyze_file
    empty_columns = [col for col in df.columns if df[col].isnull().all()]
                    ^^^^^^^^^^^^^^^^^^^^^^^^^^^^^^^^^^^^^^^^^^^^^^^^^^^^^
  File "C:\Users\Sai Varma\Desktop\Enterprise_Data_Cleaning\backend\services\analysis_service.py", line 36, in <listcomp>
    empty_columns = [col for col in df.columns if df[col].isnull().all()]
                    ^^^^^^^^^^^^^^^^^^^^^^^^^^^^^^^^^^^^^^^^^^^^^^^^^^^^^
  File "C:\Users\Sai Varma\AppData\Local\Programs\Python\Python311\Lib\site-packages\pandas\core\generic.py", line 1519, in __nonzero__
    raise ValueError(
ValueError: The truth value of a Series is ambiguous. Use a.empty, a.bool(), a.item(), a.any() or a.all().
2025-03-26 17:37:51,420 - EnterpriseDataCleaning - ERROR - Error during file analysis:
Traceback (most recent call last):
  File "C:\Users\Sai Varma\Desktop\Enterprise_Data_Cleaning\backend\services\analysis_service.py", line 36, in analyze_file
    empty_columns = [col for col in df.columns if df[col].isnull().all()]
                    ^^^^^^^^^^^^^^^^^^^^^^^^^^^^^^^^^^^^^^^^^^^^^^^^^^^^^
  File "C:\Users\Sai Varma\Desktop\Enterprise_Data_Cleaning\backend\services\analysis_service.py", line 36, in <listcomp>
    empty_columns = [col for col in df.columns if df[col].isnull().all()]
                    ^^^^^^^^^^^^^^^^^^^^^^^^^^^^^^^^^^^^^^^^^^^^^^^^^^^^^
  File "C:\Users\Sai Varma\AppData\Local\Programs\Python\Python311\Lib\site-packages\pandas\core\generic.py", line 1519, in __nonzero__
    raise ValueError(
ValueError: The truth value of a Series is ambiguous. Use a.empty, a.bool(), a.item(), a.any() or a.all().
2025-03-26 17:37:51,421 - EnterpriseDataCleaning - ERROR - Error during file analysis:
Traceback (most recent call last):
  File "C:\Users\Sai Varma\Desktop\Enterprise_Data_Cleaning\backend\routes\file_routes.py", line 57, in analyze_file
    analysis = analysis_service.analyze_file(file_path)
               ^^^^^^^^^^^^^^^^^^^^^^^^^^^^^^^^^^^^^^^^
  File "C:\Users\Sai Varma\Desktop\Enterprise_Data_Cleaning\backend\services\analysis_service.py", line 79, in analyze_file
    raise e
  File "C:\Users\Sai Varma\Desktop\Enterprise_Data_Cleaning\backend\services\analysis_service.py", line 36, in analyze_file
    empty_columns = [col for col in df.columns if df[col].isnull().all()]
                    ^^^^^^^^^^^^^^^^^^^^^^^^^^^^^^^^^^^^^^^^^^^^^^^^^^^^^
  File "C:\Users\Sai Varma\Desktop\Enterprise_Data_Cleaning\backend\services\analysis_service.py", line 36, in <listcomp>
    empty_columns = [col for col in df.columns if df[col].isnull().all()]
                    ^^^^^^^^^^^^^^^^^^^^^^^^^^^^^^^^^^^^^^^^^^^^^^^^^^^^^
  File "C:\Users\Sai Varma\AppData\Local\Programs\Python\Python311\Lib\site-packages\pandas\core\generic.py", line 1519, in __nonzero__
    raise ValueError(
ValueError: The truth value of a Series is ambiguous. Use a.empty, a.bool(), a.item(), a.any() or a.all().
2025-03-26 17:39:56,279 - EnterpriseDataCleaning - ERROR - Error during file analysis:
Traceback (most recent call last):
  File "C:\Users\Sai Varma\Desktop\Enterprise_Data_Cleaning\backend\services\analysis_service.py", line 37, in analyze_file
    empty_columns = [col for col in df.columns if bool(df[col].isnull().all())]
                    ^^^^^^^^^^^^^^^^^^^^^^^^^^^^^^^^^^^^^^^^^^^^^^^^^^^^^^^^^^^
  File "C:\Users\Sai Varma\Desktop\Enterprise_Data_Cleaning\backend\services\analysis_service.py", line 37, in <listcomp>
    empty_columns = [col for col in df.columns if bool(df[col].isnull().all())]
                                                  ^^^^^^^^^^^^^^^^^^^^^^^^^^^^
  File "C:\Users\Sai Varma\AppData\Local\Programs\Python\Python311\Lib\site-packages\pandas\core\generic.py", line 1519, in __nonzero__
    raise ValueError(
ValueError: The truth value of a Series is ambiguous. Use a.empty, a.bool(), a.item(), a.any() or a.all().
2025-03-26 17:39:56,284 - EnterpriseDataCleaning - ERROR - Error during file analysis:
Traceback (most recent call last):
  File "C:\Users\Sai Varma\Desktop\Enterprise_Data_Cleaning\backend\routes\file_routes.py", line 57, in analyze_file
    analysis = analysis_service.analyze_file(file_path)
               ^^^^^^^^^^^^^^^^^^^^^^^^^^^^^^^^^^^^^^^^
  File "C:\Users\Sai Varma\Desktop\Enterprise_Data_Cleaning\backend\services\analysis_service.py", line 80, in analyze_file
    raise e
  File "C:\Users\Sai Varma\Desktop\Enterprise_Data_Cleaning\backend\services\analysis_service.py", line 37, in analyze_file
    empty_columns = [col for col in df.columns if bool(df[col].isnull().all())]
                    ^^^^^^^^^^^^^^^^^^^^^^^^^^^^^^^^^^^^^^^^^^^^^^^^^^^^^^^^^^^
  File "C:\Users\Sai Varma\Desktop\Enterprise_Data_Cleaning\backend\services\analysis_service.py", line 37, in <listcomp>
    empty_columns = [col for col in df.columns if bool(df[col].isnull().all())]
                                                  ^^^^^^^^^^^^^^^^^^^^^^^^^^^^
  File "C:\Users\Sai Varma\AppData\Local\Programs\Python\Python311\Lib\site-packages\pandas\core\generic.py", line 1519, in __nonzero__
    raise ValueError(
ValueError: The truth value of a Series is ambiguous. Use a.empty, a.bool(), a.item(), a.any() or a.all().
2025-03-26 17:39:57,401 - EnterpriseDataCleaning - ERROR - Error during file analysis:
Traceback (most recent call last):
  File "C:\Users\Sai Varma\Desktop\Enterprise_Data_Cleaning\backend\services\analysis_service.py", line 37, in analyze_file
    empty_columns = [col for col in df.columns if bool(df[col].isnull().all())]
                    ^^^^^^^^^^^^^^^^^^^^^^^^^^^^^^^^^^^^^^^^^^^^^^^^^^^^^^^^^^^
  File "C:\Users\Sai Varma\Desktop\Enterprise_Data_Cleaning\backend\services\analysis_service.py", line 37, in <listcomp>
    empty_columns = [col for col in df.columns if bool(df[col].isnull().all())]
                                                  ^^^^^^^^^^^^^^^^^^^^^^^^^^^^
  File "C:\Users\Sai Varma\AppData\Local\Programs\Python\Python311\Lib\site-packages\pandas\core\generic.py", line 1519, in __nonzero__
    raise ValueError(
ValueError: The truth value of a Series is ambiguous. Use a.empty, a.bool(), a.item(), a.any() or a.all().
2025-03-26 17:39:57,405 - EnterpriseDataCleaning - ERROR - Error during file analysis:
Traceback (most recent call last):
  File "C:\Users\Sai Varma\Desktop\Enterprise_Data_Cleaning\backend\routes\file_routes.py", line 57, in analyze_file
    analysis = analysis_service.analyze_file(file_path)
               ^^^^^^^^^^^^^^^^^^^^^^^^^^^^^^^^^^^^^^^^
  File "C:\Users\Sai Varma\Desktop\Enterprise_Data_Cleaning\backend\services\analysis_service.py", line 80, in analyze_file
    raise e
  File "C:\Users\Sai Varma\Desktop\Enterprise_Data_Cleaning\backend\services\analysis_service.py", line 37, in analyze_file
    empty_columns = [col for col in df.columns if bool(df[col].isnull().all())]
                    ^^^^^^^^^^^^^^^^^^^^^^^^^^^^^^^^^^^^^^^^^^^^^^^^^^^^^^^^^^^
  File "C:\Users\Sai Varma\Desktop\Enterprise_Data_Cleaning\backend\services\analysis_service.py", line 37, in <listcomp>
    empty_columns = [col for col in df.columns if bool(df[col].isnull().all())]
                                                  ^^^^^^^^^^^^^^^^^^^^^^^^^^^^
  File "C:\Users\Sai Varma\AppData\Local\Programs\Python\Python311\Lib\site-packages\pandas\core\generic.py", line 1519, in __nonzero__
    raise ValueError(
ValueError: The truth value of a Series is ambiguous. Use a.empty, a.bool(), a.item(), a.any() or a.all().
2025-03-26 17:39:57,966 - EnterpriseDataCleaning - ERROR - Error during file analysis:
Traceback (most recent call last):
  File "C:\Users\Sai Varma\Desktop\Enterprise_Data_Cleaning\backend\services\analysis_service.py", line 37, in analyze_file
    empty_columns = [col for col in df.columns if bool(df[col].isnull().all())]
                    ^^^^^^^^^^^^^^^^^^^^^^^^^^^^^^^^^^^^^^^^^^^^^^^^^^^^^^^^^^^
  File "C:\Users\Sai Varma\Desktop\Enterprise_Data_Cleaning\backend\services\analysis_service.py", line 37, in <listcomp>
    empty_columns = [col for col in df.columns if bool(df[col].isnull().all())]
                                                  ^^^^^^^^^^^^^^^^^^^^^^^^^^^^
  File "C:\Users\Sai Varma\AppData\Local\Programs\Python\Python311\Lib\site-packages\pandas\core\generic.py", line 1519, in __nonzero__
    raise ValueError(
ValueError: The truth value of a Series is ambiguous. Use a.empty, a.bool(), a.item(), a.any() or a.all().
2025-03-26 17:39:57,967 - EnterpriseDataCleaning - ERROR - Error during file analysis:
Traceback (most recent call last):
  File "C:\Users\Sai Varma\Desktop\Enterprise_Data_Cleaning\backend\routes\file_routes.py", line 57, in analyze_file
    analysis = analysis_service.analyze_file(file_path)
               ^^^^^^^^^^^^^^^^^^^^^^^^^^^^^^^^^^^^^^^^
  File "C:\Users\Sai Varma\Desktop\Enterprise_Data_Cleaning\backend\services\analysis_service.py", line 80, in analyze_file
    raise e
  File "C:\Users\Sai Varma\Desktop\Enterprise_Data_Cleaning\backend\services\analysis_service.py", line 37, in analyze_file
    empty_columns = [col for col in df.columns if bool(df[col].isnull().all())]
                    ^^^^^^^^^^^^^^^^^^^^^^^^^^^^^^^^^^^^^^^^^^^^^^^^^^^^^^^^^^^
  File "C:\Users\Sai Varma\Desktop\Enterprise_Data_Cleaning\backend\services\analysis_service.py", line 37, in <listcomp>
    empty_columns = [col for col in df.columns if bool(df[col].isnull().all())]
                                                  ^^^^^^^^^^^^^^^^^^^^^^^^^^^^
  File "C:\Users\Sai Varma\AppData\Local\Programs\Python\Python311\Lib\site-packages\pandas\core\generic.py", line 1519, in __nonzero__
    raise ValueError(
ValueError: The truth value of a Series is ambiguous. Use a.empty, a.bool(), a.item(), a.any() or a.all().
2025-03-26 17:39:58,345 - EnterpriseDataCleaning - ERROR - Error during file analysis:
Traceback (most recent call last):
  File "C:\Users\Sai Varma\Desktop\Enterprise_Data_Cleaning\backend\services\analysis_service.py", line 37, in analyze_file
    empty_columns = [col for col in df.columns if bool(df[col].isnull().all())]
                    ^^^^^^^^^^^^^^^^^^^^^^^^^^^^^^^^^^^^^^^^^^^^^^^^^^^^^^^^^^^
  File "C:\Users\Sai Varma\Desktop\Enterprise_Data_Cleaning\backend\services\analysis_service.py", line 37, in <listcomp>
    empty_columns = [col for col in df.columns if bool(df[col].isnull().all())]
                                                  ^^^^^^^^^^^^^^^^^^^^^^^^^^^^
  File "C:\Users\Sai Varma\AppData\Local\Programs\Python\Python311\Lib\site-packages\pandas\core\generic.py", line 1519, in __nonzero__
    raise ValueError(
ValueError: The truth value of a Series is ambiguous. Use a.empty, a.bool(), a.item(), a.any() or a.all().
2025-03-26 17:39:58,347 - EnterpriseDataCleaning - ERROR - Error during file analysis:
Traceback (most recent call last):
  File "C:\Users\Sai Varma\Desktop\Enterprise_Data_Cleaning\backend\routes\file_routes.py", line 57, in analyze_file
    analysis = analysis_service.analyze_file(file_path)
               ^^^^^^^^^^^^^^^^^^^^^^^^^^^^^^^^^^^^^^^^
  File "C:\Users\Sai Varma\Desktop\Enterprise_Data_Cleaning\backend\services\analysis_service.py", line 80, in analyze_file
    raise e
  File "C:\Users\Sai Varma\Desktop\Enterprise_Data_Cleaning\backend\services\analysis_service.py", line 37, in analyze_file
    empty_columns = [col for col in df.columns if bool(df[col].isnull().all())]
                    ^^^^^^^^^^^^^^^^^^^^^^^^^^^^^^^^^^^^^^^^^^^^^^^^^^^^^^^^^^^
  File "C:\Users\Sai Varma\Desktop\Enterprise_Data_Cleaning\backend\services\analysis_service.py", line 37, in <listcomp>
    empty_columns = [col for col in df.columns if bool(df[col].isnull().all())]
                                                  ^^^^^^^^^^^^^^^^^^^^^^^^^^^^
  File "C:\Users\Sai Varma\AppData\Local\Programs\Python\Python311\Lib\site-packages\pandas\core\generic.py", line 1519, in __nonzero__
    raise ValueError(
ValueError: The truth value of a Series is ambiguous. Use a.empty, a.bool(), a.item(), a.any() or a.all().
2025-03-26 17:39:59,005 - EnterpriseDataCleaning - ERROR - Error during file analysis:
Traceback (most recent call last):
  File "C:\Users\Sai Varma\Desktop\Enterprise_Data_Cleaning\backend\services\analysis_service.py", line 37, in analyze_file
    empty_columns = [col for col in df.columns if bool(df[col].isnull().all())]
                    ^^^^^^^^^^^^^^^^^^^^^^^^^^^^^^^^^^^^^^^^^^^^^^^^^^^^^^^^^^^
  File "C:\Users\Sai Varma\Desktop\Enterprise_Data_Cleaning\backend\services\analysis_service.py", line 37, in <listcomp>
    empty_columns = [col for col in df.columns if bool(df[col].isnull().all())]
                                                  ^^^^^^^^^^^^^^^^^^^^^^^^^^^^
  File "C:\Users\Sai Varma\AppData\Local\Programs\Python\Python311\Lib\site-packages\pandas\core\generic.py", line 1519, in __nonzero__
    raise ValueError(
ValueError: The truth value of a Series is ambiguous. Use a.empty, a.bool(), a.item(), a.any() or a.all().
2025-03-26 17:39:59,006 - EnterpriseDataCleaning - ERROR - Error during file analysis:
Traceback (most recent call last):
  File "C:\Users\Sai Varma\Desktop\Enterprise_Data_Cleaning\backend\routes\file_routes.py", line 57, in analyze_file
    analysis = analysis_service.analyze_file(file_path)
               ^^^^^^^^^^^^^^^^^^^^^^^^^^^^^^^^^^^^^^^^
  File "C:\Users\Sai Varma\Desktop\Enterprise_Data_Cleaning\backend\services\analysis_service.py", line 80, in analyze_file
    raise e
  File "C:\Users\Sai Varma\Desktop\Enterprise_Data_Cleaning\backend\services\analysis_service.py", line 37, in analyze_file
    empty_columns = [col for col in df.columns if bool(df[col].isnull().all())]
                    ^^^^^^^^^^^^^^^^^^^^^^^^^^^^^^^^^^^^^^^^^^^^^^^^^^^^^^^^^^^
  File "C:\Users\Sai Varma\Desktop\Enterprise_Data_Cleaning\backend\services\analysis_service.py", line 37, in <listcomp>
    empty_columns = [col for col in df.columns if bool(df[col].isnull().all())]
                                                  ^^^^^^^^^^^^^^^^^^^^^^^^^^^^
  File "C:\Users\Sai Varma\AppData\Local\Programs\Python\Python311\Lib\site-packages\pandas\core\generic.py", line 1519, in __nonzero__
    raise ValueError(
ValueError: The truth value of a Series is ambiguous. Use a.empty, a.bool(), a.item(), a.any() or a.all().
2025-03-26 17:39:59,296 - EnterpriseDataCleaning - ERROR - Error during file analysis:
Traceback (most recent call last):
  File "C:\Users\Sai Varma\Desktop\Enterprise_Data_Cleaning\backend\services\analysis_service.py", line 37, in analyze_file
    empty_columns = [col for col in df.columns if bool(df[col].isnull().all())]
                    ^^^^^^^^^^^^^^^^^^^^^^^^^^^^^^^^^^^^^^^^^^^^^^^^^^^^^^^^^^^
  File "C:\Users\Sai Varma\Desktop\Enterprise_Data_Cleaning\backend\services\analysis_service.py", line 37, in <listcomp>
    empty_columns = [col for col in df.columns if bool(df[col].isnull().all())]
                                                  ^^^^^^^^^^^^^^^^^^^^^^^^^^^^
  File "C:\Users\Sai Varma\AppData\Local\Programs\Python\Python311\Lib\site-packages\pandas\core\generic.py", line 1519, in __nonzero__
    raise ValueError(
ValueError: The truth value of a Series is ambiguous. Use a.empty, a.bool(), a.item(), a.any() or a.all().
2025-03-26 17:39:59,297 - EnterpriseDataCleaning - ERROR - Error during file analysis:
Traceback (most recent call last):
  File "C:\Users\Sai Varma\Desktop\Enterprise_Data_Cleaning\backend\routes\file_routes.py", line 57, in analyze_file
    analysis = analysis_service.analyze_file(file_path)
               ^^^^^^^^^^^^^^^^^^^^^^^^^^^^^^^^^^^^^^^^
  File "C:\Users\Sai Varma\Desktop\Enterprise_Data_Cleaning\backend\services\analysis_service.py", line 80, in analyze_file
    raise e
  File "C:\Users\Sai Varma\Desktop\Enterprise_Data_Cleaning\backend\services\analysis_service.py", line 37, in analyze_file
    empty_columns = [col for col in df.columns if bool(df[col].isnull().all())]
                    ^^^^^^^^^^^^^^^^^^^^^^^^^^^^^^^^^^^^^^^^^^^^^^^^^^^^^^^^^^^
  File "C:\Users\Sai Varma\Desktop\Enterprise_Data_Cleaning\backend\services\analysis_service.py", line 37, in <listcomp>
    empty_columns = [col for col in df.columns if bool(df[col].isnull().all())]
                                                  ^^^^^^^^^^^^^^^^^^^^^^^^^^^^
  File "C:\Users\Sai Varma\AppData\Local\Programs\Python\Python311\Lib\site-packages\pandas\core\generic.py", line 1519, in __nonzero__
    raise ValueError(
ValueError: The truth value of a Series is ambiguous. Use a.empty, a.bool(), a.item(), a.any() or a.all().
2025-03-26 17:40:01,858 - EnterpriseDataCleaning - ERROR - Error during file analysis:
Traceback (most recent call last):
  File "C:\Users\Sai Varma\Desktop\Enterprise_Data_Cleaning\backend\services\analysis_service.py", line 37, in analyze_file
    empty_columns = [col for col in df.columns if bool(df[col].isnull().all())]
                    ^^^^^^^^^^^^^^^^^^^^^^^^^^^^^^^^^^^^^^^^^^^^^^^^^^^^^^^^^^^
  File "C:\Users\Sai Varma\Desktop\Enterprise_Data_Cleaning\backend\services\analysis_service.py", line 37, in <listcomp>
    empty_columns = [col for col in df.columns if bool(df[col].isnull().all())]
                                                  ^^^^^^^^^^^^^^^^^^^^^^^^^^^^
  File "C:\Users\Sai Varma\AppData\Local\Programs\Python\Python311\Lib\site-packages\pandas\core\generic.py", line 1519, in __nonzero__
    raise ValueError(
ValueError: The truth value of a Series is ambiguous. Use a.empty, a.bool(), a.item(), a.any() or a.all().
2025-03-26 17:40:01,860 - EnterpriseDataCleaning - ERROR - Error during file analysis:
Traceback (most recent call last):
  File "C:\Users\Sai Varma\Desktop\Enterprise_Data_Cleaning\backend\routes\file_routes.py", line 57, in analyze_file
    analysis = analysis_service.analyze_file(file_path)
               ^^^^^^^^^^^^^^^^^^^^^^^^^^^^^^^^^^^^^^^^
  File "C:\Users\Sai Varma\Desktop\Enterprise_Data_Cleaning\backend\services\analysis_service.py", line 80, in analyze_file
    raise e
  File "C:\Users\Sai Varma\Desktop\Enterprise_Data_Cleaning\backend\services\analysis_service.py", line 37, in analyze_file
    empty_columns = [col for col in df.columns if bool(df[col].isnull().all())]
                    ^^^^^^^^^^^^^^^^^^^^^^^^^^^^^^^^^^^^^^^^^^^^^^^^^^^^^^^^^^^
  File "C:\Users\Sai Varma\Desktop\Enterprise_Data_Cleaning\backend\services\analysis_service.py", line 37, in <listcomp>
    empty_columns = [col for col in df.columns if bool(df[col].isnull().all())]
                                                  ^^^^^^^^^^^^^^^^^^^^^^^^^^^^
  File "C:\Users\Sai Varma\AppData\Local\Programs\Python\Python311\Lib\site-packages\pandas\core\generic.py", line 1519, in __nonzero__
    raise ValueError(
ValueError: The truth value of a Series is ambiguous. Use a.empty, a.bool(), a.item(), a.any() or a.all().
2025-03-26 17:40:02,673 - EnterpriseDataCleaning - ERROR - Error during file analysis:
Traceback (most recent call last):
  File "C:\Users\Sai Varma\Desktop\Enterprise_Data_Cleaning\backend\services\analysis_service.py", line 37, in analyze_file
    empty_columns = [col for col in df.columns if bool(df[col].isnull().all())]
                    ^^^^^^^^^^^^^^^^^^^^^^^^^^^^^^^^^^^^^^^^^^^^^^^^^^^^^^^^^^^
  File "C:\Users\Sai Varma\Desktop\Enterprise_Data_Cleaning\backend\services\analysis_service.py", line 37, in <listcomp>
    empty_columns = [col for col in df.columns if bool(df[col].isnull().all())]
                                                  ^^^^^^^^^^^^^^^^^^^^^^^^^^^^
  File "C:\Users\Sai Varma\AppData\Local\Programs\Python\Python311\Lib\site-packages\pandas\core\generic.py", line 1519, in __nonzero__
    raise ValueError(
ValueError: The truth value of a Series is ambiguous. Use a.empty, a.bool(), a.item(), a.any() or a.all().
2025-03-26 17:40:02,675 - EnterpriseDataCleaning - ERROR - Error during file analysis:
Traceback (most recent call last):
  File "C:\Users\Sai Varma\Desktop\Enterprise_Data_Cleaning\backend\routes\file_routes.py", line 57, in analyze_file
    analysis = analysis_service.analyze_file(file_path)
               ^^^^^^^^^^^^^^^^^^^^^^^^^^^^^^^^^^^^^^^^
  File "C:\Users\Sai Varma\Desktop\Enterprise_Data_Cleaning\backend\services\analysis_service.py", line 80, in analyze_file
    raise e
  File "C:\Users\Sai Varma\Desktop\Enterprise_Data_Cleaning\backend\services\analysis_service.py", line 37, in analyze_file
    empty_columns = [col for col in df.columns if bool(df[col].isnull().all())]
                    ^^^^^^^^^^^^^^^^^^^^^^^^^^^^^^^^^^^^^^^^^^^^^^^^^^^^^^^^^^^
  File "C:\Users\Sai Varma\Desktop\Enterprise_Data_Cleaning\backend\services\analysis_service.py", line 37, in <listcomp>
    empty_columns = [col for col in df.columns if bool(df[col].isnull().all())]
                                                  ^^^^^^^^^^^^^^^^^^^^^^^^^^^^
  File "C:\Users\Sai Varma\AppData\Local\Programs\Python\Python311\Lib\site-packages\pandas\core\generic.py", line 1519, in __nonzero__
    raise ValueError(
ValueError: The truth value of a Series is ambiguous. Use a.empty, a.bool(), a.item(), a.any() or a.all().
2025-03-26 17:40:57,992 - EnterpriseDataCleaning - ERROR - Error during file analysis:
Traceback (most recent call last):
  File "C:\Users\Sai Varma\Desktop\Enterprise_Data_Cleaning\backend\services\analysis_service.py", line 37, in analyze_file
    empty_columns = [col for col in df.columns if df[col].isnull().all() == True]
                    ^^^^^^^^^^^^^^^^^^^^^^^^^^^^^^^^^^^^^^^^^^^^^^^^^^^^^^^^^^^^^
  File "C:\Users\Sai Varma\Desktop\Enterprise_Data_Cleaning\backend\services\analysis_service.py", line 37, in <listcomp>
    empty_columns = [col for col in df.columns if df[col].isnull().all() == True]
                                                  ^^^^^^^^^^^^^^^^^^^^^^^^^^^^^^
  File "C:\Users\Sai Varma\AppData\Local\Programs\Python\Python311\Lib\site-packages\pandas\core\generic.py", line 1519, in __nonzero__
    raise ValueError(
ValueError: The truth value of a Series is ambiguous. Use a.empty, a.bool(), a.item(), a.any() or a.all().
2025-03-26 17:40:58,000 - EnterpriseDataCleaning - ERROR - Error during file analysis:
Traceback (most recent call last):
  File "C:\Users\Sai Varma\Desktop\Enterprise_Data_Cleaning\backend\routes\file_routes.py", line 57, in analyze_file
    analysis = analysis_service.analyze_file(file_path)
               ^^^^^^^^^^^^^^^^^^^^^^^^^^^^^^^^^^^^^^^^
  File "C:\Users\Sai Varma\Desktop\Enterprise_Data_Cleaning\backend\services\analysis_service.py", line 80, in analyze_file
    raise e
  File "C:\Users\Sai Varma\Desktop\Enterprise_Data_Cleaning\backend\services\analysis_service.py", line 37, in analyze_file
    empty_columns = [col for col in df.columns if df[col].isnull().all() == True]
                    ^^^^^^^^^^^^^^^^^^^^^^^^^^^^^^^^^^^^^^^^^^^^^^^^^^^^^^^^^^^^^
  File "C:\Users\Sai Varma\Desktop\Enterprise_Data_Cleaning\backend\services\analysis_service.py", line 37, in <listcomp>
    empty_columns = [col for col in df.columns if df[col].isnull().all() == True]
                                                  ^^^^^^^^^^^^^^^^^^^^^^^^^^^^^^
  File "C:\Users\Sai Varma\AppData\Local\Programs\Python\Python311\Lib\site-packages\pandas\core\generic.py", line 1519, in __nonzero__
    raise ValueError(
ValueError: The truth value of a Series is ambiguous. Use a.empty, a.bool(), a.item(), a.any() or a.all().
2025-03-26 17:40:58,764 - EnterpriseDataCleaning - ERROR - Error during file analysis:
Traceback (most recent call last):
  File "C:\Users\Sai Varma\Desktop\Enterprise_Data_Cleaning\backend\services\analysis_service.py", line 37, in analyze_file
    empty_columns = [col for col in df.columns if df[col].isnull().all() == True]
                    ^^^^^^^^^^^^^^^^^^^^^^^^^^^^^^^^^^^^^^^^^^^^^^^^^^^^^^^^^^^^^
  File "C:\Users\Sai Varma\Desktop\Enterprise_Data_Cleaning\backend\services\analysis_service.py", line 37, in <listcomp>
    empty_columns = [col for col in df.columns if df[col].isnull().all() == True]
                                                  ^^^^^^^^^^^^^^^^^^^^^^^^^^^^^^
  File "C:\Users\Sai Varma\AppData\Local\Programs\Python\Python311\Lib\site-packages\pandas\core\generic.py", line 1519, in __nonzero__
    raise ValueError(
ValueError: The truth value of a Series is ambiguous. Use a.empty, a.bool(), a.item(), a.any() or a.all().
2025-03-26 17:40:58,766 - EnterpriseDataCleaning - ERROR - Error during file analysis:
Traceback (most recent call last):
  File "C:\Users\Sai Varma\Desktop\Enterprise_Data_Cleaning\backend\routes\file_routes.py", line 57, in analyze_file
    analysis = analysis_service.analyze_file(file_path)
               ^^^^^^^^^^^^^^^^^^^^^^^^^^^^^^^^^^^^^^^^
  File "C:\Users\Sai Varma\Desktop\Enterprise_Data_Cleaning\backend\services\analysis_service.py", line 80, in analyze_file
    raise e
  File "C:\Users\Sai Varma\Desktop\Enterprise_Data_Cleaning\backend\services\analysis_service.py", line 37, in analyze_file
    empty_columns = [col for col in df.columns if df[col].isnull().all() == True]
                    ^^^^^^^^^^^^^^^^^^^^^^^^^^^^^^^^^^^^^^^^^^^^^^^^^^^^^^^^^^^^^
  File "C:\Users\Sai Varma\Desktop\Enterprise_Data_Cleaning\backend\services\analysis_service.py", line 37, in <listcomp>
    empty_columns = [col for col in df.columns if df[col].isnull().all() == True]
                                                  ^^^^^^^^^^^^^^^^^^^^^^^^^^^^^^
  File "C:\Users\Sai Varma\AppData\Local\Programs\Python\Python311\Lib\site-packages\pandas\core\generic.py", line 1519, in __nonzero__
    raise ValueError(
ValueError: The truth value of a Series is ambiguous. Use a.empty, a.bool(), a.item(), a.any() or a.all().
2025-03-26 17:40:59,327 - EnterpriseDataCleaning - ERROR - Error during file analysis:
Traceback (most recent call last):
  File "C:\Users\Sai Varma\Desktop\Enterprise_Data_Cleaning\backend\services\analysis_service.py", line 37, in analyze_file
    empty_columns = [col for col in df.columns if df[col].isnull().all() == True]
                    ^^^^^^^^^^^^^^^^^^^^^^^^^^^^^^^^^^^^^^^^^^^^^^^^^^^^^^^^^^^^^
  File "C:\Users\Sai Varma\Desktop\Enterprise_Data_Cleaning\backend\services\analysis_service.py", line 37, in <listcomp>
    empty_columns = [col for col in df.columns if df[col].isnull().all() == True]
                                                  ^^^^^^^^^^^^^^^^^^^^^^^^^^^^^^
  File "C:\Users\Sai Varma\AppData\Local\Programs\Python\Python311\Lib\site-packages\pandas\core\generic.py", line 1519, in __nonzero__
    raise ValueError(
ValueError: The truth value of a Series is ambiguous. Use a.empty, a.bool(), a.item(), a.any() or a.all().
2025-03-26 17:40:59,328 - EnterpriseDataCleaning - ERROR - Error during file analysis:
Traceback (most recent call last):
  File "C:\Users\Sai Varma\Desktop\Enterprise_Data_Cleaning\backend\routes\file_routes.py", line 57, in analyze_file
    analysis = analysis_service.analyze_file(file_path)
               ^^^^^^^^^^^^^^^^^^^^^^^^^^^^^^^^^^^^^^^^
  File "C:\Users\Sai Varma\Desktop\Enterprise_Data_Cleaning\backend\services\analysis_service.py", line 80, in analyze_file
    raise e
  File "C:\Users\Sai Varma\Desktop\Enterprise_Data_Cleaning\backend\services\analysis_service.py", line 37, in analyze_file
    empty_columns = [col for col in df.columns if df[col].isnull().all() == True]
                    ^^^^^^^^^^^^^^^^^^^^^^^^^^^^^^^^^^^^^^^^^^^^^^^^^^^^^^^^^^^^^
  File "C:\Users\Sai Varma\Desktop\Enterprise_Data_Cleaning\backend\services\analysis_service.py", line 37, in <listcomp>
    empty_columns = [col for col in df.columns if df[col].isnull().all() == True]
                                                  ^^^^^^^^^^^^^^^^^^^^^^^^^^^^^^
  File "C:\Users\Sai Varma\AppData\Local\Programs\Python\Python311\Lib\site-packages\pandas\core\generic.py", line 1519, in __nonzero__
    raise ValueError(
ValueError: The truth value of a Series is ambiguous. Use a.empty, a.bool(), a.item(), a.any() or a.all().
2025-03-26 17:40:59,572 - EnterpriseDataCleaning - ERROR - Error during file analysis:
Traceback (most recent call last):
  File "C:\Users\Sai Varma\Desktop\Enterprise_Data_Cleaning\backend\services\analysis_service.py", line 37, in analyze_file
    empty_columns = [col for col in df.columns if df[col].isnull().all() == True]
                    ^^^^^^^^^^^^^^^^^^^^^^^^^^^^^^^^^^^^^^^^^^^^^^^^^^^^^^^^^^^^^
  File "C:\Users\Sai Varma\Desktop\Enterprise_Data_Cleaning\backend\services\analysis_service.py", line 37, in <listcomp>
    empty_columns = [col for col in df.columns if df[col].isnull().all() == True]
                                                  ^^^^^^^^^^^^^^^^^^^^^^^^^^^^^^
  File "C:\Users\Sai Varma\AppData\Local\Programs\Python\Python311\Lib\site-packages\pandas\core\generic.py", line 1519, in __nonzero__
    raise ValueError(
ValueError: The truth value of a Series is ambiguous. Use a.empty, a.bool(), a.item(), a.any() or a.all().
2025-03-26 17:40:59,576 - EnterpriseDataCleaning - ERROR - Error during file analysis:
Traceback (most recent call last):
  File "C:\Users\Sai Varma\Desktop\Enterprise_Data_Cleaning\backend\routes\file_routes.py", line 57, in analyze_file
    analysis = analysis_service.analyze_file(file_path)
               ^^^^^^^^^^^^^^^^^^^^^^^^^^^^^^^^^^^^^^^^
  File "C:\Users\Sai Varma\Desktop\Enterprise_Data_Cleaning\backend\services\analysis_service.py", line 80, in analyze_file
    raise e
  File "C:\Users\Sai Varma\Desktop\Enterprise_Data_Cleaning\backend\services\analysis_service.py", line 37, in analyze_file
    empty_columns = [col for col in df.columns if df[col].isnull().all() == True]
                    ^^^^^^^^^^^^^^^^^^^^^^^^^^^^^^^^^^^^^^^^^^^^^^^^^^^^^^^^^^^^^
  File "C:\Users\Sai Varma\Desktop\Enterprise_Data_Cleaning\backend\services\analysis_service.py", line 37, in <listcomp>
    empty_columns = [col for col in df.columns if df[col].isnull().all() == True]
                                                  ^^^^^^^^^^^^^^^^^^^^^^^^^^^^^^
  File "C:\Users\Sai Varma\AppData\Local\Programs\Python\Python311\Lib\site-packages\pandas\core\generic.py", line 1519, in __nonzero__
    raise ValueError(
ValueError: The truth value of a Series is ambiguous. Use a.empty, a.bool(), a.item(), a.any() or a.all().
2025-03-26 17:41:00,164 - EnterpriseDataCleaning - ERROR - Error during file analysis:
Traceback (most recent call last):
  File "C:\Users\Sai Varma\Desktop\Enterprise_Data_Cleaning\backend\services\analysis_service.py", line 37, in analyze_file
    empty_columns = [col for col in df.columns if df[col].isnull().all() == True]
                    ^^^^^^^^^^^^^^^^^^^^^^^^^^^^^^^^^^^^^^^^^^^^^^^^^^^^^^^^^^^^^
  File "C:\Users\Sai Varma\Desktop\Enterprise_Data_Cleaning\backend\services\analysis_service.py", line 37, in <listcomp>
    empty_columns = [col for col in df.columns if df[col].isnull().all() == True]
                                                  ^^^^^^^^^^^^^^^^^^^^^^^^^^^^^^
  File "C:\Users\Sai Varma\AppData\Local\Programs\Python\Python311\Lib\site-packages\pandas\core\generic.py", line 1519, in __nonzero__
    raise ValueError(
ValueError: The truth value of a Series is ambiguous. Use a.empty, a.bool(), a.item(), a.any() or a.all().
2025-03-26 17:41:00,166 - EnterpriseDataCleaning - ERROR - Error during file analysis:
Traceback (most recent call last):
  File "C:\Users\Sai Varma\Desktop\Enterprise_Data_Cleaning\backend\routes\file_routes.py", line 57, in analyze_file
    analysis = analysis_service.analyze_file(file_path)
               ^^^^^^^^^^^^^^^^^^^^^^^^^^^^^^^^^^^^^^^^
  File "C:\Users\Sai Varma\Desktop\Enterprise_Data_Cleaning\backend\services\analysis_service.py", line 80, in analyze_file
    raise e
  File "C:\Users\Sai Varma\Desktop\Enterprise_Data_Cleaning\backend\services\analysis_service.py", line 37, in analyze_file
    empty_columns = [col for col in df.columns if df[col].isnull().all() == True]
                    ^^^^^^^^^^^^^^^^^^^^^^^^^^^^^^^^^^^^^^^^^^^^^^^^^^^^^^^^^^^^^
  File "C:\Users\Sai Varma\Desktop\Enterprise_Data_Cleaning\backend\services\analysis_service.py", line 37, in <listcomp>
    empty_columns = [col for col in df.columns if df[col].isnull().all() == True]
                                                  ^^^^^^^^^^^^^^^^^^^^^^^^^^^^^^
  File "C:\Users\Sai Varma\AppData\Local\Programs\Python\Python311\Lib\site-packages\pandas\core\generic.py", line 1519, in __nonzero__
    raise ValueError(
ValueError: The truth value of a Series is ambiguous. Use a.empty, a.bool(), a.item(), a.any() or a.all().
2025-03-26 17:41:00,410 - EnterpriseDataCleaning - ERROR - Error during file analysis:
Traceback (most recent call last):
  File "C:\Users\Sai Varma\Desktop\Enterprise_Data_Cleaning\backend\services\analysis_service.py", line 37, in analyze_file
    empty_columns = [col for col in df.columns if df[col].isnull().all() == True]
                    ^^^^^^^^^^^^^^^^^^^^^^^^^^^^^^^^^^^^^^^^^^^^^^^^^^^^^^^^^^^^^
  File "C:\Users\Sai Varma\Desktop\Enterprise_Data_Cleaning\backend\services\analysis_service.py", line 37, in <listcomp>
    empty_columns = [col for col in df.columns if df[col].isnull().all() == True]
                                                  ^^^^^^^^^^^^^^^^^^^^^^^^^^^^^^
  File "C:\Users\Sai Varma\AppData\Local\Programs\Python\Python311\Lib\site-packages\pandas\core\generic.py", line 1519, in __nonzero__
    raise ValueError(
ValueError: The truth value of a Series is ambiguous. Use a.empty, a.bool(), a.item(), a.any() or a.all().
2025-03-26 17:41:00,411 - EnterpriseDataCleaning - ERROR - Error during file analysis:
Traceback (most recent call last):
  File "C:\Users\Sai Varma\Desktop\Enterprise_Data_Cleaning\backend\routes\file_routes.py", line 57, in analyze_file
    analysis = analysis_service.analyze_file(file_path)
               ^^^^^^^^^^^^^^^^^^^^^^^^^^^^^^^^^^^^^^^^
  File "C:\Users\Sai Varma\Desktop\Enterprise_Data_Cleaning\backend\services\analysis_service.py", line 80, in analyze_file
    raise e
  File "C:\Users\Sai Varma\Desktop\Enterprise_Data_Cleaning\backend\services\analysis_service.py", line 37, in analyze_file
    empty_columns = [col for col in df.columns if df[col].isnull().all() == True]
                    ^^^^^^^^^^^^^^^^^^^^^^^^^^^^^^^^^^^^^^^^^^^^^^^^^^^^^^^^^^^^^
  File "C:\Users\Sai Varma\Desktop\Enterprise_Data_Cleaning\backend\services\analysis_service.py", line 37, in <listcomp>
    empty_columns = [col for col in df.columns if df[col].isnull().all() == True]
                                                  ^^^^^^^^^^^^^^^^^^^^^^^^^^^^^^
  File "C:\Users\Sai Varma\AppData\Local\Programs\Python\Python311\Lib\site-packages\pandas\core\generic.py", line 1519, in __nonzero__
    raise ValueError(
ValueError: The truth value of a Series is ambiguous. Use a.empty, a.bool(), a.item(), a.any() or a.all().
2025-03-26 17:41:00,659 - EnterpriseDataCleaning - ERROR - Error during file analysis:
Traceback (most recent call last):
  File "C:\Users\Sai Varma\Desktop\Enterprise_Data_Cleaning\backend\services\analysis_service.py", line 37, in analyze_file
    empty_columns = [col for col in df.columns if df[col].isnull().all() == True]
                    ^^^^^^^^^^^^^^^^^^^^^^^^^^^^^^^^^^^^^^^^^^^^^^^^^^^^^^^^^^^^^
  File "C:\Users\Sai Varma\Desktop\Enterprise_Data_Cleaning\backend\services\analysis_service.py", line 37, in <listcomp>
    empty_columns = [col for col in df.columns if df[col].isnull().all() == True]
                                                  ^^^^^^^^^^^^^^^^^^^^^^^^^^^^^^
  File "C:\Users\Sai Varma\AppData\Local\Programs\Python\Python311\Lib\site-packages\pandas\core\generic.py", line 1519, in __nonzero__
    raise ValueError(
ValueError: The truth value of a Series is ambiguous. Use a.empty, a.bool(), a.item(), a.any() or a.all().
2025-03-26 17:41:00,660 - EnterpriseDataCleaning - ERROR - Error during file analysis:
Traceback (most recent call last):
  File "C:\Users\Sai Varma\Desktop\Enterprise_Data_Cleaning\backend\routes\file_routes.py", line 57, in analyze_file
    analysis = analysis_service.analyze_file(file_path)
               ^^^^^^^^^^^^^^^^^^^^^^^^^^^^^^^^^^^^^^^^
  File "C:\Users\Sai Varma\Desktop\Enterprise_Data_Cleaning\backend\services\analysis_service.py", line 80, in analyze_file
    raise e
  File "C:\Users\Sai Varma\Desktop\Enterprise_Data_Cleaning\backend\services\analysis_service.py", line 37, in analyze_file
    empty_columns = [col for col in df.columns if df[col].isnull().all() == True]
                    ^^^^^^^^^^^^^^^^^^^^^^^^^^^^^^^^^^^^^^^^^^^^^^^^^^^^^^^^^^^^^
  File "C:\Users\Sai Varma\Desktop\Enterprise_Data_Cleaning\backend\services\analysis_service.py", line 37, in <listcomp>
    empty_columns = [col for col in df.columns if df[col].isnull().all() == True]
                                                  ^^^^^^^^^^^^^^^^^^^^^^^^^^^^^^
  File "C:\Users\Sai Varma\AppData\Local\Programs\Python\Python311\Lib\site-packages\pandas\core\generic.py", line 1519, in __nonzero__
    raise ValueError(
ValueError: The truth value of a Series is ambiguous. Use a.empty, a.bool(), a.item(), a.any() or a.all().
2025-03-26 17:41:00,907 - EnterpriseDataCleaning - ERROR - Error during file analysis:
Traceback (most recent call last):
  File "C:\Users\Sai Varma\Desktop\Enterprise_Data_Cleaning\backend\services\analysis_service.py", line 37, in analyze_file
    empty_columns = [col for col in df.columns if df[col].isnull().all() == True]
                    ^^^^^^^^^^^^^^^^^^^^^^^^^^^^^^^^^^^^^^^^^^^^^^^^^^^^^^^^^^^^^
  File "C:\Users\Sai Varma\Desktop\Enterprise_Data_Cleaning\backend\services\analysis_service.py", line 37, in <listcomp>
    empty_columns = [col for col in df.columns if df[col].isnull().all() == True]
                                                  ^^^^^^^^^^^^^^^^^^^^^^^^^^^^^^
  File "C:\Users\Sai Varma\AppData\Local\Programs\Python\Python311\Lib\site-packages\pandas\core\generic.py", line 1519, in __nonzero__
    raise ValueError(
ValueError: The truth value of a Series is ambiguous. Use a.empty, a.bool(), a.item(), a.any() or a.all().
2025-03-26 17:41:00,909 - EnterpriseDataCleaning - ERROR - Error during file analysis:
Traceback (most recent call last):
  File "C:\Users\Sai Varma\Desktop\Enterprise_Data_Cleaning\backend\routes\file_routes.py", line 57, in analyze_file
    analysis = analysis_service.analyze_file(file_path)
               ^^^^^^^^^^^^^^^^^^^^^^^^^^^^^^^^^^^^^^^^
  File "C:\Users\Sai Varma\Desktop\Enterprise_Data_Cleaning\backend\services\analysis_service.py", line 80, in analyze_file
    raise e
  File "C:\Users\Sai Varma\Desktop\Enterprise_Data_Cleaning\backend\services\analysis_service.py", line 37, in analyze_file
    empty_columns = [col for col in df.columns if df[col].isnull().all() == True]
                    ^^^^^^^^^^^^^^^^^^^^^^^^^^^^^^^^^^^^^^^^^^^^^^^^^^^^^^^^^^^^^
  File "C:\Users\Sai Varma\Desktop\Enterprise_Data_Cleaning\backend\services\analysis_service.py", line 37, in <listcomp>
    empty_columns = [col for col in df.columns if df[col].isnull().all() == True]
                                                  ^^^^^^^^^^^^^^^^^^^^^^^^^^^^^^
  File "C:\Users\Sai Varma\AppData\Local\Programs\Python\Python311\Lib\site-packages\pandas\core\generic.py", line 1519, in __nonzero__
    raise ValueError(
ValueError: The truth value of a Series is ambiguous. Use a.empty, a.bool(), a.item(), a.any() or a.all().
2025-03-26 17:41:11,893 - EnterpriseDataCleaning - INFO - File analysis complete.
2025-03-26 17:41:42,351 - EnterpriseDataCleaning - ERROR - Error during data cleaning:
Traceback (most recent call last):
  File "C:\Users\Sai Varma\Desktop\Enterprise_Data_Cleaning\backend\services\data_cleaning.py", line 23, in clean_data
    writer.book = book
    ^^^^^^^^^^^
AttributeError: property 'book' of 'OpenpyxlWriter' object has no setter

During handling of the above exception, another exception occurred:

Traceback (most recent call last):
  File "C:\Users\Sai Varma\Desktop\Enterprise_Data_Cleaning\backend\routes\file_routes.py", line 38, in clean_file
    result_path = data_cleaning.clean_data(file_path)
                  ^^^^^^^^^^^^^^^^^^^^^^^^^^^^^^^^^^^
  File "C:\Users\Sai Varma\Desktop\Enterprise_Data_Cleaning\backend\services\data_cleaning.py", line 22, in clean_data
    with pd.ExcelWriter(file_path, engine='openpyxl') as writer:
  File "C:\Users\Sai Varma\AppData\Local\Programs\Python\Python311\Lib\site-packages\pandas\io\excel\_base.py", line 1370, in __exit__
    self.close()
  File "C:\Users\Sai Varma\AppData\Local\Programs\Python\Python311\Lib\site-packages\pandas\io\excel\_base.py", line 1374, in close
    self._save()
  File "C:\Users\Sai Varma\AppData\Local\Programs\Python\Python311\Lib\site-packages\pandas\io\excel\_openpyxl.py", line 110, in _save
    self.book.save(self._handles.handle)
  File "C:\Users\Sai Varma\AppData\Local\Programs\Python\Python311\Lib\site-packages\openpyxl\workbook\workbook.py", line 386, in save
    save_workbook(self, filename)
  File "C:\Users\Sai Varma\AppData\Local\Programs\Python\Python311\Lib\site-packages\openpyxl\writer\excel.py", line 294, in save_workbook
    writer.save()
  File "C:\Users\Sai Varma\AppData\Local\Programs\Python\Python311\Lib\site-packages\openpyxl\writer\excel.py", line 275, in save
    self.write_data()
  File "C:\Users\Sai Varma\AppData\Local\Programs\Python\Python311\Lib\site-packages\openpyxl\writer\excel.py", line 89, in write_data
    archive.writestr(ARC_WORKBOOK, writer.write())
                                   ^^^^^^^^^^^^^^
  File "C:\Users\Sai Varma\AppData\Local\Programs\Python\Python311\Lib\site-packages\openpyxl\workbook\_writer.py", line 150, in write
    self.write_views()
  File "C:\Users\Sai Varma\AppData\Local\Programs\Python\Python311\Lib\site-packages\openpyxl\workbook\_writer.py", line 137, in write_views
    active = get_active_sheet(self.wb)
             ^^^^^^^^^^^^^^^^^^^^^^^^^
  File "C:\Users\Sai Varma\AppData\Local\Programs\Python\Python311\Lib\site-packages\openpyxl\workbook\_writer.py", line 35, in get_active_sheet
    raise IndexError("At least one sheet must be visible")
IndexError: At least one sheet must be visible
2025-03-26 17:53:52,375 - EnterpriseDataCleaning - ERROR - Error during file analysis:
Traceback (most recent call last):
  File "C:\Users\Sai Varma\Desktop\Enterprise_Data_Cleaning\backend\services\analysis_service.py", line 10, in analyze_file
    wb = openpyxl.load_workbook(file_path, read_only=True)
         ^^^^^^^^^^^^^^^^^^^^^^^^^^^^^^^^^^^^^^^^^^^^^^^^^
  File "C:\Users\Sai Varma\AppData\Local\Programs\Python\Python311\Lib\site-packages\openpyxl\reader\excel.py", line 346, in load_workbook
    reader.read()
  File "C:\Users\Sai Varma\AppData\Local\Programs\Python\Python311\Lib\site-packages\openpyxl\reader\excel.py", line 287, in read
    self.read_manifest()
  File "C:\Users\Sai Varma\AppData\Local\Programs\Python\Python311\Lib\site-packages\openpyxl\reader\excel.py", line 134, in read_manifest
    src = self.archive.read(ARC_CONTENT_TYPES)
          ^^^^^^^^^^^^^^^^^^^^^^^^^^^^^^^^^^^^
  File "C:\Users\Sai Varma\AppData\Local\Programs\Python\Python311\Lib\zipfile.py", line 1510, in read
    with self.open(name, "r", pwd) as fp:
         ^^^^^^^^^^^^^^^^^^^^^^^^^
  File "C:\Users\Sai Varma\AppData\Local\Programs\Python\Python311\Lib\zipfile.py", line 1547, in open
    zinfo = self.getinfo(name)
            ^^^^^^^^^^^^^^^^^^
  File "C:\Users\Sai Varma\AppData\Local\Programs\Python\Python311\Lib\zipfile.py", line 1476, in getinfo
    raise KeyError(
KeyError: "There is no item named '[Content_Types].xml' in the archive"
2025-03-26 17:53:52,417 - EnterpriseDataCleaning - ERROR - Error during file analysis:
Traceback (most recent call last):
  File "C:\Users\Sai Varma\Desktop\Enterprise_Data_Cleaning\backend\routes\file_routes.py", line 57, in analyze_file
    analysis = analysis_service.analyze_file(file_path)
               ^^^^^^^^^^^^^^^^^^^^^^^^^^^^^^^^^^^^^^^^
  File "C:\Users\Sai Varma\Desktop\Enterprise_Data_Cleaning\backend\services\analysis_service.py", line 63, in analyze_file
    raise e
  File "C:\Users\Sai Varma\Desktop\Enterprise_Data_Cleaning\backend\services\analysis_service.py", line 10, in analyze_file
    wb = openpyxl.load_workbook(file_path, read_only=True)
         ^^^^^^^^^^^^^^^^^^^^^^^^^^^^^^^^^^^^^^^^^^^^^^^^^
  File "C:\Users\Sai Varma\AppData\Local\Programs\Python\Python311\Lib\site-packages\openpyxl\reader\excel.py", line 346, in load_workbook
    reader.read()
  File "C:\Users\Sai Varma\AppData\Local\Programs\Python\Python311\Lib\site-packages\openpyxl\reader\excel.py", line 287, in read
    self.read_manifest()
  File "C:\Users\Sai Varma\AppData\Local\Programs\Python\Python311\Lib\site-packages\openpyxl\reader\excel.py", line 134, in read_manifest
    src = self.archive.read(ARC_CONTENT_TYPES)
          ^^^^^^^^^^^^^^^^^^^^^^^^^^^^^^^^^^^^
  File "C:\Users\Sai Varma\AppData\Local\Programs\Python\Python311\Lib\zipfile.py", line 1510, in read
    with self.open(name, "r", pwd) as fp:
         ^^^^^^^^^^^^^^^^^^^^^^^^^
  File "C:\Users\Sai Varma\AppData\Local\Programs\Python\Python311\Lib\zipfile.py", line 1547, in open
    zinfo = self.getinfo(name)
            ^^^^^^^^^^^^^^^^^^
  File "C:\Users\Sai Varma\AppData\Local\Programs\Python\Python311\Lib\zipfile.py", line 1476, in getinfo
    raise KeyError(
KeyError: "There is no item named '[Content_Types].xml' in the archive"
2025-03-26 17:54:21,515 - EnterpriseDataCleaning - INFO - File saved: data/uploads\Example-3.xlsx
2025-03-26 17:54:22,286 - EnterpriseDataCleaning - INFO - File analysis complete.
2025-03-26 17:54:35,067 - EnterpriseDataCleaning - INFO - File analysis complete.
2025-03-26 17:54:41,806 - EnterpriseDataCleaning - INFO - File saved: data/uploads\Example-2.xlsx
2025-03-26 17:54:42,488 - EnterpriseDataCleaning - INFO - File analysis complete.
